Workbook

Sheet Cara
A1: Langkah Pengerjaan (NB: Bagi yang sebelumnya sudah sempat mengerjakan dan hasilnya masih X, bisa di copy paste rumusnya kesini ya, jika secara rumus benar maka akan mendapatkan hasil yang benar juga, mohon maaf atas ketidaknyamanannya)
A2: 1 | B2: Isi sheet Helper dengan nilai yang valid (ada nilai valid apa di kolom Jurusan)
A3: 2 | B3: Cek apakah ada data invalid dari sheet Main berdasarkan kamus yang ada di sheet Helper, jika ada silahkan ditandai dengan lingkaran
A4: 3 | B4: Jawab pertanyaan nomor 1-3 dari sheet Soal
A5: 4 | B5: Perbaiki data yang invalid sehingga semua data dari sheet Main menjadi valid (berdasarkan sheet Helper)
A6: 5 | B6: Buat 3 grafik dengan contoh seperti ini
A18: 6 | B18: Jawab pertanyaan nomor 4-6 dari sheet Soal
A19: 7 | B19: Buat ID Mahasiswa dari Sheet Main berdasarkan Kode Jurusan + Nomor mereka
B20: Contoh
B21: Nomor | C21: Jurusan | D21: ID Mahasiswa
B22: 1 | C22: Matematika | D22: A0001
B23: 10 | C23: Fisika | D23: B0010
B24: 100 | C24: Kimia | D24: C0100
B25: 1000 | C25: Biologi | D25: D1000
B26: 98 | C26: Statistika | D26: E0098
B27: 908 | C27: Aktuaria | D27: F0908
A28: 8 | B28: Isi kolom Absen dari Sheet Main berdasarkan data dari Sheet Absen
B29: Jika mahasiswa berada di data Absen, isi dengan tanggal dia absen
B30: Jika tidak ada, isi dengan kalimat No
A31: 9 | B31: Jawab pertanyaan nomor 7-9 dari sheet Soal
A32: 10 | B32: Isi kolom Nilai Akhir dengan kriteria berikut
B33: Ujian 1 hingga Ujian 4 | C33: Masing-masing 12.5%
B34: UTS dan UAS | C34: Masing-masing 20%
B35: Tugas | C35: 0.1
B36: Untuk mahasiswa yang pernah absen mengurangi nilai Tugas sebanyak 10
B37: Misal
B38: Tugas | C38: 80
B39: Absen | C39: Yes
B40: Tugas | C40: 80-10= 70
A41: 11 | B41: Isi kolom Nama dari sheet Main berdasarkan data dari sheet Detail
A42: 12 | B42: Jawab pertanyaan nomor 10-12 dari sheet Soal
A43: 13 | B43: Beri Grade berdasarkan kondisi berikut ini
B44: A+ | C44: 90 keatas
B45: A | C45: 80,01 sampai 90
B46: B | C46: 70,01 sampai 80
B47: C | C47: 60,01 sampai 70
B48: D | C48: 40,01 sampai 60
B49: E | C49: 40 dan bawah bawahnya
A50: 14 | B50: Jawab pertanyaan nomor 13-15 dari sheet Soal

Sheet Main
A1: Nomor | B1: ID Mahasiswa | C1: Jurusan | D1: Nama | E1: Ujian 1 | F1: Ujian 2 | G1: UTS | H1: Ujian 3 | I1: Ujian 4 | J1: UAS | K1: Tugas | L1: Absen | M1: Tugas Update | N1: Nilai Akhir | O1: Grade | P1: Tanggal Lahir | Q1: Kota | R1: Tinggi Badan | S1: Berat Badan | T1: Alamat | U1: Golongan Darah | V1: Dosen | W1: Gol darah | X1: kalo pakai xlookup
A2: 16 | B2: =CONCATENATE("A",TEXT(Main!A2,"0000")) -> A0016 | C2: Matematika | D2: =VLOOKUP(B2,Detail!$G$1:$H$1001,2,FALSE) -> Baktiono Kurniawan | E2: 72 | F2: 64 | G2: 79 | H2: 59 | I2: 82 | J2: 88 | K2: 69 | L2: =IFERROR(VLOOKUP(B2,Absen!$A$1:$C$501,2,FALSE),"No") -> 44828 | M2: =IF(L2="no",K2,K2-10)*10% -> 5.9 | N2: =SUM(E2*12.5%,F2*12.5%,H2*12.5%,I2*12.5%,G2*20%,J2*20%,M2) -> 73.925 | O2: =VLOOKUP(N2,Helper!$B$30:$C$35,2,TRUE) -> B | P2: =INDEX(Detail!$A$1:$A$1001,MATCH(B2,Detail!$G$1:$G$1001,0)) -> 37464 | Q2: =INDEX(Detail!$F$1:$F$1001,MATCH(Main!B2,Detail!$G$1:$G$1001,0)) -> Padangpanjang | R2: =INDEX(Detail!$C$1:$C$1001,MATCH(B2,Detail!$G$1:$G$1001,0),1) -> 159 | S2: =INDEX(Detail!$D$1:$D$1001,MATCH(B2,Detail!$G$1:$G$1001,0),1) -> 56 | T2: =INDEX(Detail!$E$1:$E$1001,MATCH(Main!B2,Detail!$G$1:$G$1001,0)) -> Gang Ahmad Dahlan No. 37 | U2: =INDEX(Detail!$B$1:$B$1001,MATCH(B2,Detail!$G$1:$G$1001,0),1) -> O- | V2: {=INDEX(Dosen!$B$3:$E$8,MATCH(Main!C2,Dosen!$A$3:$A$8,0),IF(AND(Main!A2>=1,Main!A2<=250),1,IF(AND(Main!A2>=251,Main!A2<=500),2,IF(AND(Main!A2>=501,Main!A2<=750),3,4))))} -> Bu Dwi | W2: =_xlfn.XLOOKUP(B2,Detail!$G$1:$G$1001,Detail!$B$1:$B$1001) -> O- | X2: =_xlfn.FORMULATEXT(W2) -> =XLOOKUP(B2;Detail!$G$1:$G$1001;Detail!$B$1:$B$1001)
A3: 20 | B3: =CONCATENATE("A",TEXT(Main!A3,"0000")) -> A0020 | C3: Matematika | D3: =VLOOKUP(B3,Detail!$G$1:$H$1001,2,FALSE) -> Halima Marbun | E3: 60 | F3: 69 | G3: 93 | H3: 72 | I3: 60 | J3: 100 | K3: 70 | L3: =IFERROR(VLOOKUP(B3,Absen!$A$1:$C$501,2,FALSE),"No") -> 44762 | M3: =IF(L3="no",K3,K3-10)*10% -> 6 | N3: =SUM(E3*12.5%,F3*12.5%,H3*12.5%,I3*12.5%,G3*20%,J3*20%,M3) -> 77.225 | O3: =VLOOKUP(N3,Helper!$B$30:$C$35,2,TRUE) -> B | P3: =INDEX(Detail!$A$1:$A$1001,MATCH(B3,Detail!$G$1:$G$1001,0)) -> 37957 | Q3: =INDEX(Detail!$F$1:$F$1001,MATCH(Main!B3,Detail!$G$1:$G$1001,0)) -> Palu | R3: =INDEX(Detail!$C$1:$C$1001,MATCH(B3,Detail!$G$1:$G$1001,0),1) -> 160 | S3: =INDEX(Detail!$D$1:$D$1001,MATCH(B3,Detail!$G$1:$G$1001,0),1) -> 73 | T3: =INDEX(Detail!$E$1:$E$1001,MATCH(Main!B3,Detail!$G$1:$G$1001,0)) -> Jl. Gedebage Selatan No. 4 | U3: =INDEX(Detail!$B$1:$B$1001,MATCH(B3,Detail!$G$1:$G$1001,0),1) -> O+ | V3: {=INDEX(Dosen!$B$3:$E$8,MATCH(Main!C3,Dosen!$A$3:$A$8,0),IF(AND(Main!A3>=1,Main!A3<=250),1,IF(AND(Main!A3>=251,Main!A3<=500),2,IF(AND(Main!A3>=501,Main!A3<=750),3,4))))} -> Bu Dwi | W3: =_xlfn.XLOOKUP(B3,Detail!$G$1:$G$1001,Detail!$B$1:$B$1001) -> O+
A4: 22 | B4: =CONCATENATE("A",TEXT(Main!A4,"0000")) -> A0022 | C4: Matematika | D4: =VLOOKUP(B4,Detail!$G$1:$H$1001,2,FALSE) -> Ira Firgantoro | E4: 51 | F4: 42 | G4: 38 | H4: 73 | I4: 63 | J4: 52 | K4: 71 | L4: =IFERROR(VLOOKUP(B4,Absen!$A$1:$C$501,2,FALSE),"No") -> No | M4: =IF(L4="no",K4,K4-10)*10% -> 7.1 | N4: =SUM(E4*12.5%,F4*12.5%,H4*12.5%,I4*12.5%,G4*20%,J4*20%,M4) -> 53.725 | O4: =VLOOKUP(N4,Helper!$B$30:$C$35,2,TRUE) -> D | P4: =INDEX(Detail!$A$1:$A$1001,MATCH(B4,Detail!$G$1:$G$1001,0)) -> 37815 | Q4: =INDEX(Detail!$F$1:$F$1001,MATCH(Main!B4,Detail!$G$1:$G$1001,0)) -> Banjarbaru | R4: =INDEX(Detail!$C$1:$C$1001,MATCH(B4,Detail!$G$1:$G$1001,0),1) -> 173 | S4: =INDEX(Detail!$D$1:$D$1001,MATCH(B4,Detail!$G$1:$G$1001,0),1) -> 86 | T4: =INDEX(Detail!$E$1:$E$1001,MATCH(Main!B4,Detail!$G$1:$G$1001,0)) -> Gg. Kutai No. 02 | U4: =INDEX(Detail!$B$1:$B$1001,MATCH(B4,Detail!$G$1:$G$1001,0),1) -> AB- | V4: {=INDEX(Dosen!$B$3:$E$8,MATCH(Main!C4,Dosen!$A$3:$A$8,0),IF(AND(Main!A4>=1,Main!A4<=250),1,IF(AND(Main!A4>=251,Main!A4<=500),2,IF(AND(Main!A4>=501,Main!A4<=750),3,4))))} -> Bu Dwi | W4: =_xlfn.XLOOKUP(B4,Detail!$G$1:$G$1001,Detail!$B$1:$B$1001) -> AB-
A5: 26 | B5: =CONCATENATE("A",TEXT(Main!A5,"0000")) -> A0026 | C5: Matematika | D5: =VLOOKUP(B5,Detail!$G$1:$H$1001,2,FALSE) -> Samsul Kusmawati | E5: 74 | F5: 57 | G5: 49 | H5: 53 | I5: 70 | J5: 57 | K5: 63 | L5: =IFERROR(VLOOKUP(B5,Absen!$A$1:$C$501,2,FALSE),"No") -> 44811 | M5: =IF(L5="no",K5,K5-10)*10% -> 5.3 | N5: =SUM(E5*12.5%,F5*12.5%,H5*12.5%,I5*12.5%,G5*20%,J5*20%,M5) -> 58.25 | O5: =VLOOKUP(N5,Helper!$B$30:$C$35,2,TRUE) -> D | P5: =INDEX(Detail!$A$1:$A$1001,MATCH(B5,Detail!$G$1:$G$1001,0)) -> 37135 | Q5: =INDEX(Detail!$F$1:$F$1001,MATCH(Main!B5,Detail!$G$1:$G$1001,0)) -> Lubuklinggau | R5: =INDEX(Detail!$C$1:$C$1001,MATCH(B5,Detail!$G$1:$G$1001,0),1) -> 156 | S5: =INDEX(Detail!$D$1:$D$1001,MATCH(B5,Detail!$G$1:$G$1001,0),1) -> 86 | T5: =INDEX(Detail!$E$1:$E$1001,MATCH(Main!B5,Detail!$G$1:$G$1001,0)) -> Gang Otto Iskandardinata No. 1 | U5: =INDEX(Detail!$B$1:$B$1001,MATCH(B5,Detail!$G$1:$G$1001,0),1) -> A+ | V5: {=INDEX(Dosen!$B$3:$E$8,MATCH(Main!C5,Dosen!$A$3:$A$8,0),IF(AND(Main!A5>=1,Main!A5<=250),1,IF(AND(Main!A5>=251,Main!A5<=500),2,IF(AND(Main!A5>=501,Main!A5<=750),3,4))))} -> Bu Dwi | W5: =_xlfn.XLOOKUP(B5,Detail!$G$1:$G$1001,Detail!$B$1:$B$1001) -> A+
A6: 31 | B6: =CONCATENATE("A",TEXT(Main!A6,"0000")) -> A0031 | C6: Matematika | D6: =VLOOKUP(B6,Detail!$G$1:$H$1001,2,FALSE) -> Koko Suartini | E6: 75 | F6: 60 | G6: 55 | H6: 74 | I6: 91 | J6: 65 | K6: 81 | L6: =IFERROR(VLOOKUP(B6,Absen!$A$1:$C$501,2,FALSE),"No") -> No | M6: =IF(L6="no",K6,K6-10)*10% -> 8.1 | N6: =SUM(E6*12.5%,F6*12.5%,H6*12.5%,I6*12.5%,G6*20%,J6*20%,M6) -> 69.6 | O6: =VLOOKUP(N6,Helper!$B$30:$C$35,2,TRUE) -> C | P6: =INDEX(Detail!$A$1:$A$1001,MATCH(B6,Detail!$G$1:$G$1001,0)) -> 38316 | Q6: =INDEX(Detail!$F$1:$F$1001,MATCH(Main!B6,Detail!$G$1:$G$1001,0)) -> Lubuklinggau | R6: =INDEX(Detail!$C$1:$C$1001,MATCH(B6,Detail!$G$1:$G$1001,0),1) -> 175 | S6: =INDEX(Detail!$D$1:$D$1001,MATCH(B6,Detail!$G$1:$G$1001,0),1) -> 87 | T6: =INDEX(Detail!$E$1:$E$1001,MATCH(Main!B6,Detail!$G$1:$G$1001,0)) -> Jl. Moch. Toha No. 97 | U6: =INDEX(Detail!$B$1:$B$1001,MATCH(B6,Detail!$G$1:$G$1001,0),1) -> O+ | V6: {=INDEX(Dosen!$B$3:$E$8,MATCH(Main!C6,Dosen!$A$3:$A$8,0),IF(AND(Main!A6>=1,Main!A6<=250),1,IF(AND(Main!A6>=251,Main!A6<=500),2,IF(AND(Main!A6>=501,Main!A6<=750),3,4))))} -> Bu Dwi | W6: =_xlfn.XLOOKUP(B6,Detail!$G$1:$G$1001,Detail!$B$1:$B$1001) -> O+
A7: 33 | B7: =CONCATENATE("A",TEXT(Main!A7,"0000")) -> A0033 | C7: Matematika | D7: =VLOOKUP(B7,Detail!$G$1:$H$1001,2,FALSE) -> Dalimin Natsir | E7: 73 | F7: 64 | G7: 40 | H7: 61 | I7: 89 | J7: 75 | K7: 65 | L7: =IFERROR(VLOOKUP(B7,Absen!$A$1:$C$501,2,FALSE),"No") -> 44880 | M7: =IF(L7="no",K7,K7-10)*10% -> 5.5 | N7: =SUM(E7*12.5%,F7*12.5%,H7*12.5%,I7*12.5%,G7*20%,J7*20%,M7) -> 64.375 | O7: =VLOOKUP(N7,Helper!$B$30:$C$35,2,TRUE) -> C | P7: =INDEX(Detail!$A$1:$A$1001,MATCH(B7,Detail!$G$1:$G$1001,0)) -> 37644 | Q7: =INDEX(Detail!$F$1:$F$1001,MATCH(Main!B7,Detail!$G$1:$G$1001,0)) -> Padang Sidempuan | R7: =INDEX(Detail!$C$1:$C$1001,MATCH(B7,Detail!$G$1:$G$1001,0),1) -> 174 | S7: =INDEX(Detail!$D$1:$D$1001,MATCH(B7,Detail!$G$1:$G$1001,0),1) -> 86 | T7: =INDEX(Detail!$E$1:$E$1001,MATCH(Main!B7,Detail!$G$1:$G$1001,0)) -> Jalan Jayawijaya No. 91 | U7: =INDEX(Detail!$B$1:$B$1001,MATCH(B7,Detail!$G$1:$G$1001,0),1) -> B- | V7: {=INDEX(Dosen!$B$3:$E$8,MATCH(Main!C7,Dosen!$A$3:$A$8,0),IF(AND(Main!A7>=1,Main!A7<=250),1,IF(AND(Main!A7>=251,Main!A7<=500),2,IF(AND(Main!A7>=501,Main!A7<=750),3,4))))} -> Bu Dwi | W7: =_xlfn.XLOOKUP(B7,Detail!$G$1:$G$1001,Detail!$B$1:$B$1001) -> B-
A8: 34 | B8: =CONCATENATE("A",TEXT(Main!A8,"0000")) -> A0034 | C8: Matematika | D8: =VLOOKUP(B8,Detail!$G$1:$H$1001,2,FALSE) -> Paulin Januar | E8: 58 | F8: 57 | G8: 78 | H8: 55 | I8: 63 | J8: 49 | K8: 94 | L8: =IFERROR(VLOOKUP(B8,Absen!$A$1:$C$501,2,FALSE),"No") -> 44765 | M8: =IF(L8="no",K8,K8-10)*10% -> 8.4 | N8: =SUM(E8*12.5%,F8*12.5%,H8*12.5%,I8*12.5%,G8*20%,J8*20%,M8) -> 62.925 | O8: =VLOOKUP(N8,Helper!$B$30:$C$35,2,TRUE) -> C | P8: =INDEX(Detail!$A$1:$A$1001,MATCH(B8,Detail!$G$1:$G$1001,0)) -> 38456 | Q8: =INDEX(Detail!$F$1:$F$1001,MATCH(Main!B8,Detail!$G$1:$G$1001,0)) -> Kota Administrasi Jakarta Selatan | R8: =INDEX(Detail!$C$1:$C$1001,MATCH(B8,Detail!$G$1:$G$1001,0),1) -> 151 | S8: =INDEX(Detail!$D$1:$D$1001,MATCH(B8,Detail!$G$1:$G$1001,0),1) -> 72 | T8: =INDEX(Detail!$E$1:$E$1001,MATCH(Main!B8,Detail!$G$1:$G$1001,0)) -> Jalan Cikutra Timur No. 51 | U8: =INDEX(Detail!$B$1:$B$1001,MATCH(B8,Detail!$G$1:$G$1001,0),1) -> AB- | V8: {=INDEX(Dosen!$B$3:$E$8,MATCH(Main!C8,Dosen!$A$3:$A$8,0),IF(AND(Main!A8>=1,Main!A8<=250),1,IF(AND(Main!A8>=251,Main!A8<=500),2,IF(AND(Main!A8>=501,Main!A8<=750),3,4))))} -> Bu Dwi | W8: =_xlfn.XLOOKUP(B8,Detail!$G$1:$G$1001,Detail!$B$1:$B$1001) -> AB-
A9: 41 | B9: =CONCATENATE("A",TEXT(Main!A9,"0000")) -> A0041 | C9: Matematika | D9: =VLOOKUP(B9,Detail!$G$1:$H$1001,2,FALSE) -> Gangsa Riyanti | E9: 53 | F9: 48 | G9: 88 | H9: 59 | I9: 90 | J9: 49 | K9: 70 | L9: =IFERROR(VLOOKUP(B9,Absen!$A$1:$C$501,2,FALSE),"No") -> No | M9: =IF(L9="no",K9,K9-10)*10% -> 7 | N9: =SUM(E9*12.5%,F9*12.5%,H9*12.5%,I9*12.5%,G9*20%,J9*20%,M9) -> 65.65 | O9: =VLOOKUP(N9,Helper!$B$30:$C$35,2,TRUE) -> C | P9: =INDEX(Detail!$A$1:$A$1001,MATCH(B9,Detail!$G$1:$G$1001,0)) -> 37504 | Q9: =INDEX(Detail!$F$1:$F$1001,MATCH(Main!B9,Detail!$G$1:$G$1001,0)) -> Kota Administrasi Jakarta Timur | R9: =INDEX(Detail!$C$1:$C$1001,MATCH(B9,Detail!$G$1:$G$1001,0),1) -> 156 | S9: =INDEX(Detail!$D$1:$D$1001,MATCH(B9,Detail!$G$1:$G$1001,0),1) -> 95 | T9: =INDEX(Detail!$E$1:$E$1001,MATCH(Main!B9,Detail!$G$1:$G$1001,0)) -> Gg. M.H Thamrin No. 5 | U9: =INDEX(Detail!$B$1:$B$1001,MATCH(B9,Detail!$G$1:$G$1001,0),1) -> B+ | V9: {=INDEX(Dosen!$B$3:$E$8,MATCH(Main!C9,Dosen!$A$3:$A$8,0),IF(AND(Main!A9>=1,Main!A9<=250),1,IF(AND(Main!A9>=251,Main!A9<=500),2,IF(AND(Main!A9>=501,Main!A9<=750),3,4))))} -> Bu Dwi | W9: =_xlfn.XLOOKUP(B9,Detail!$G$1:$G$1001,Detail!$B$1:$B$1001) -> B+
A10: 51 | B10: =CONCATENATE("A",TEXT(Main!A10,"0000")) -> A0051 | C10: Matematika | D10: =VLOOKUP(B10,Detail!$G$1:$H$1001,2,FALSE) -> Jamalia Zulaika | E10: 65 | F10: 64 | G10: 62 | H10: 54 | I10: 79 | J10: 82 | K10: 76 | L10: =IFERROR(VLOOKUP(B10,Absen!$A$1:$C$501,2,FALSE),"No") -> 44771 | M10: =IF(L10="no",K10,K10-10)*10% -> 6.6 | N10: =SUM(E10*12.5%,F10*12.5%,H10*12.5%,I10*12.5%,G10*20%,J10*20%,M10) -> 68.15 | O10: =VLOOKUP(N10,Helper!$B$30:$C$35,2,TRUE) -> C | P10: =INDEX(Detail!$A$1:$A$1001,MATCH(B10,Detail!$G$1:$G$1001,0)) -> 37719 | Q10: =INDEX(Detail!$F$1:$F$1001,MATCH(Main!B10,Detail!$G$1:$G$1001,0)) -> Tanjungbalai | R10: =INDEX(Detail!$C$1:$C$1001,MATCH(B10,Detail!$G$1:$G$1001,0),1) -> 171 | S10: =INDEX(Detail!$D$1:$D$1001,MATCH(B10,Detail!$G$1:$G$1001,0),1) -> 79 | T10: =INDEX(Detail!$E$1:$E$1001,MATCH(Main!B10,Detail!$G$1:$G$1001,0)) -> Gang Surapati No. 48 | U10: =INDEX(Detail!$B$1:$B$1001,MATCH(B10,Detail!$G$1:$G$1001,0),1) -> O+ | V10: {=INDEX(Dosen!$B$3:$E$8,MATCH(Main!C10,Dosen!$A$3:$A$8,0),IF(AND(Main!A10>=1,Main!A10<=250),1,IF(AND(Main!A10>=251,Main!A10<=500),2,IF(AND(Main!A10>=501,Main!A10<=750),3,4))))} -> Bu Dwi | W10: =_xlfn.XLOOKUP(B10,Detail!$G$1:$G$1001,Detail!$B$1:$B$1001) -> O+
A11: 63 | B11: =CONCATENATE("A",TEXT(Main!A11,"0000")) -> A0063 | C11: Matematika | D11: =VLOOKUP(B11,Detail!$G$1:$H$1001,2,FALSE) -> Salwa Wasita | E11: 74 | F11: 52 | G11: 71 | H11: 59 | I11: 72 | J11: 54 | K11: 79 | L11: =IFERROR(VLOOKUP(B11,Absen!$A$1:$C$501,2,FALSE),"No") -> 44836 | M11: =IF(L11="no",K11,K11-10)*10% -> 6.9 | N11: =SUM(E11*12.5%,F11*12.5%,H11*12.5%,I11*12.5%,G11*20%,J11*20%,M11) -> 64.025 | O11: =VLOOKUP(N11,Helper!$B$30:$C$35,2,TRUE) -> C | P11: =INDEX(Detail!$A$1:$A$1001,MATCH(B11,Detail!$G$1:$G$1001,0)) -> 38293 | Q11: =INDEX(Detail!$F$1:$F$1001,MATCH(Main!B11,Detail!$G$1:$G$1001,0)) -> Salatiga | R11: =INDEX(Detail!$C$1:$C$1001,MATCH(B11,Detail!$G$1:$G$1001,0),1) -> 162 | S11: =INDEX(Detail!$D$1:$D$1001,MATCH(B11,Detail!$G$1:$G$1001,0),1) -> 84 | T11: =INDEX(Detail!$E$1:$E$1001,MATCH(Main!B11,Detail!$G$1:$G$1001,0)) -> Jl. Kiaracondong No. 45 | U11: =INDEX(Detail!$B$1:$B$1001,MATCH(B11,Detail!$G$1:$G$1001,0),1) -> AB+ | V11: {=INDEX(Dosen!$B$3:$E$8,MATCH(Main!C11,Dosen!$A$3:$A$8,0),IF(AND(Main!A11>=1,Main!A11<=250),1,IF(AND(Main!A11>=251,Main!A11<=500),2,IF(AND(Main!A11>=501,Main!A11<=750),3,4))))} -> Bu Dwi | W11: =_xlfn.XLOOKUP(B11,Detail!$G$1:$G$1001,Detail!$B$1:$B$1001) -> AB+
A12: 65 | B12: =CONCATENATE("A",TEXT(Main!A12,"0000")) -> A0065 | C12: Matematika | D12: =VLOOKUP(B12,Detail!$G$1:$H$1001,2,FALSE) -> Ajiman Mulyani | E12: 81 | F12: 41 | G12: 67 | H12: 54 | I12: 95 | J12: 52 | K12: 71 | L12: =IFERROR(VLOOKUP(B12,Absen!$A$1:$C$501,2,FALSE),"No") -> 44852 | M12: =IF(L12="no",K12,K12-10)*10% -> 6.1 | N12: =SUM(E12*12.5%,F12*12.5%,H12*12.5%,I12*12.5%,G12*20%,J12*20%,M12) -> 63.775 | O12: =VLOOKUP(N12,Helper!$B$30:$C$35,2,TRUE) -> C | P12: =INDEX(Detail!$A$1:$A$1001,MATCH(B12,Detail!$G$1:$G$1001,0)) -> 38212 | Q12: =INDEX(Detail!$F$1:$F$1001,MATCH(Main!B12,Detail!$G$1:$G$1001,0)) -> Balikpapan | R12: =INDEX(Detail!$C$1:$C$1001,MATCH(B12,Detail!$G$1:$G$1001,0),1) -> 166 | S12: =INDEX(Detail!$D$1:$D$1001,MATCH(B12,Detail!$G$1:$G$1001,0),1) -> 81 | T12: =INDEX(Detail!$E$1:$E$1001,MATCH(Main!B12,Detail!$G$1:$G$1001,0)) -> Jalan M.T Haryono No. 8 | U12: =INDEX(Detail!$B$1:$B$1001,MATCH(B12,Detail!$G$1:$G$1001,0),1) -> O+ | V12: {=INDEX(Dosen!$B$3:$E$8,MATCH(Main!C12,Dosen!$A$3:$A$8,0),IF(AND(Main!A12>=1,Main!A12<=250),1,IF(AND(Main!A12>=251,Main!A12<=500),2,IF(AND(Main!A12>=501,Main!A12<=750),3,4))))} -> Bu Dwi | W12: =_xlfn.XLOOKUP(B12,Detail!$G$1:$G$1001,Detail!$B$1:$B$1001) -> O+
A13: 83 | B13: =CONCATENATE("A",TEXT(Main!A13,"0000")) -> A0083 | C13: Matematika | D13: =VLOOKUP(B13,Detail!$G$1:$H$1001,2,FALSE) -> Keisha Suryatmi | E13: 58 | F13: 72 | G13: 75 | H13: 60 | I13: 75 | J13: 58 | K13: 93 | L13: =IFERROR(VLOOKUP(B13,Absen!$A$1:$C$501,2,FALSE),"No") -> 44762 | M13: =IF(L13="no",K13,K13-10)*10% -> 8.3 | N13: =SUM(E13*12.5%,F13*12.5%,H13*12.5%,I13*12.5%,G13*20%,J13*20%,M13) -> 68.025 | O13: =VLOOKUP(N13,Helper!$B$30:$C$35,2,TRUE) -> C | P13: =INDEX(Detail!$A$1:$A$1001,MATCH(B13,Detail!$G$1:$G$1001,0)) -> 37240 | Q13: =INDEX(Detail!$F$1:$F$1001,MATCH(Main!B13,Detail!$G$1:$G$1001,0)) -> Bau-Bau | R13: =INDEX(Detail!$C$1:$C$1001,MATCH(B13,Detail!$G$1:$G$1001,0),1) -> 160 | S13: =INDEX(Detail!$D$1:$D$1001,MATCH(B13,Detail!$G$1:$G$1001,0),1) -> 50 | T13: =INDEX(Detail!$E$1:$E$1001,MATCH(Main!B13,Detail!$G$1:$G$1001,0)) -> Jl. Bangka Raya No. 62 | U13: =INDEX(Detail!$B$1:$B$1001,MATCH(B13,Detail!$G$1:$G$1001,0),1) -> AB- | V13: {=INDEX(Dosen!$B$3:$E$8,MATCH(Main!C13,Dosen!$A$3:$A$8,0),IF(AND(Main!A13>=1,Main!A13<=250),1,IF(AND(Main!A13>=251,Main!A13<=500),2,IF(AND(Main!A13>=501,Main!A13<=750),3,4))))} -> Bu Dwi | W13: =_xlfn.XLOOKUP(B13,Detail!$G$1:$G$1001,Detail!$B$1:$B$1001) -> AB-
A14: 84 | B14: =CONCATENATE("A",TEXT(Main!A14,"0000")) -> A0084 | C14: Matematika | D14: =VLOOKUP(B14,Detail!$G$1:$H$1001,2,FALSE) -> Kadir Anggriawan | E14: 86 | F14: 61 | G14: 71 | H14: 59 | I14: 62 | J14: 45 | K14: 84 | L14: =IFERROR(VLOOKUP(B14,Absen!$A$1:$C$501,2,FALSE),"No") -> No | M14: =IF(L14="no",K14,K14-10)*10% -> 8.4 | N14: =SUM(E14*12.5%,F14*12.5%,H14*12.5%,I14*12.5%,G14*20%,J14*20%,M14) -> 65.1 | O14: =VLOOKUP(N14,Helper!$B$30:$C$35,2,TRUE) -> C | P14: =INDEX(Detail!$A$1:$A$1001,MATCH(B14,Detail!$G$1:$G$1001,0)) -> 38089 | Q14: =INDEX(Detail!$F$1:$F$1001,MATCH(Main!B14,Detail!$G$1:$G$1001,0)) -> Makassar | R14: =INDEX(Detail!$C$1:$C$1001,MATCH(B14,Detail!$G$1:$G$1001,0),1) -> 156 | S14: =INDEX(Detail!$D$1:$D$1001,MATCH(B14,Detail!$G$1:$G$1001,0),1) -> 50 | T14: =INDEX(Detail!$E$1:$E$1001,MATCH(Main!B14,Detail!$G$1:$G$1001,0)) -> Gang Waringin No. 6 | U14: =INDEX(Detail!$B$1:$B$1001,MATCH(B14,Detail!$G$1:$G$1001,0),1) -> B- | V14: {=INDEX(Dosen!$B$3:$E$8,MATCH(Main!C14,Dosen!$A$3:$A$8,0),IF(AND(Main!A14>=1,Main!A14<=250),1,IF(AND(Main!A14>=251,Main!A14<=500),2,IF(AND(Main!A14>=501,Main!A14<=750),3,4))))} -> Bu Dwi | W14: =_xlfn.XLOOKUP(B14,Detail!$G$1:$G$1001,Detail!$B$1:$B$1001) -> B-
... A160: 992 | B160: =CONCATENATE("A",TEXT(Main!A160,"0000")) -> A0992 | C160: Matematika | D160: =VLOOKUP(B160,Detail!$G$1:$H$1001,2,FALSE) -> Irfan Nababan | E160: 75 | F160: 56 | G160: 77 | H160: 53 | I160: 80 | J160: 47 | K160: 83 | L160: =IFERROR(VLOOKUP(B160,Absen!$A$1:$C$501,2,FALSE),"No") -> 44862 | M160: =IF(L160="no",K160,K160-10)*10% -> 7.3 | N160: =SUM(E160*12.5%,F160*12.5%,H160*12.5%,I160*12.5%,G160*20%,J160*20%,M160) -> 65.1 | O160: =VLOOKUP(N160,Helper!$B$30:$C$35,2,TRUE) -> C | P160: =INDEX(Detail!$A$1:$A$1001,MATCH(B160,Detail!$G$1:$G$1001,0)) -> 37631 | Q160: =INDEX(Detail!$F$1:$F$1001,MATCH(Main!B160,Detail!$G$1:$G$1001,0)) -> Denpasar | R160: =INDEX(Detail!$C$1:$C$1001,MATCH(B160,Detail!$G$1:$G$1001,0),1) -> 166 | S160: =INDEX(Detail!$D$1:$D$1001,MATCH(B160,Detail!$G$1:$G$1001,0),1) -> 78 | T160: =INDEX(Detail!$E$1:$E$1001,MATCH(Main!B160,Detail!$G$1:$G$1001,0)) -> Gang S. Parman No. 64 | U160: =INDEX(Detail!$B$1:$B$1001,MATCH(B160,Detail!$G$1:$G$1001,0),1) -> B+ | V160: {=INDEX(Dosen!$B$3:$E$8,MATCH(Main!C160,Dosen!$A$3:$A$8,0),IF(AND(Main!A160>=1,Main!A160<=250),1,IF(AND(Main!A160>=251,Main!A160<=500),2,IF(AND(Main!A160>=501,Main!A160<=750),3,4))))} -> Pak Krisna | W160: =_xlfn.XLOOKUP(B160,Detail!$G$1:$G$1001,Detail!$B$1:$B$1001) -> B+
A161: 9 | B161: =CONCATENATE("B",TEXT(A161,"0000")) -> B0009 | C161: Fisika | D161: =VLOOKUP(B161,Detail!$G$1:$H$1001,2,FALSE) -> Dina Wahyudin | E161: 77 | F161: 40 | G161: 95 | H161: 75 | I161: 60 | J161: 81 | K161: 73 | L161: =IFERROR(VLOOKUP(B161,Absen!$A$1:$C$501,2,FALSE),"No") -> 44807 | M161: =IF(L161="no",K161,K161-10)*10% -> 6.3 | N161: =SUM(E161*12.5%,F161*12.5%,H161*12.5%,I161*12.5%,G161*20%,J161*20%,M161) -> 73 | O161: =VLOOKUP(N161,Helper!$B$30:$C$35,2,TRUE) -> B | P161: =INDEX(Detail!$A$1:$A$1001,MATCH(B161,Detail!$G$1:$G$1001,0)) -> 37544 | Q161: =INDEX(Detail!$F$1:$F$1001,MATCH(Main!B161,Detail!$G$1:$G$1001,0)) -> Gorontalo | R161: =INDEX(Detail!$C$1:$C$1001,MATCH(B161,Detail!$G$1:$G$1001,0),1) -> 158 | S161: =INDEX(Detail!$D$1:$D$1001,MATCH(B161,Detail!$G$1:$G$1001,0),1) -> 76 | T161: =INDEX(Detail!$E$1:$E$1001,MATCH(Main!B161,Detail!$G$1:$G$1001,0)) -> Gg. Cempaka No. 58 | U161: =INDEX(Detail!$B$1:$B$1001,MATCH(B161,Detail!$G$1:$G$1001,0),1) -> AB+ | V161: {=INDEX(Dosen!$B$3:$E$8,MATCH(Main!C161,Dosen!$A$3:$A$8,0),IF(AND(Main!A161>=1,Main!A161<=250),1,IF(AND(Main!A161>=251,Main!A161<=500),2,IF(AND(Main!A161>=501,Main!A161<=750),3,4))))} -> Pak Krisna | W161: =_xlfn.XLOOKUP(B161,Detail!$G$1:$G$1001,Detail!$B$1:$B$1001) -> AB+
A162: 11 | B162: =CONCATENATE("B",TEXT(A162,"0000")) -> B0011 | C162: Fisika | D162: =VLOOKUP(B162,Detail!$G$1:$H$1001,2,FALSE) -> Lukita Anggriawan | E162: 80 | F162: 75 | G162: 51 | H162: 52 | I162: 54 | J162: 51 | K162: 79 | L162: =IFERROR(VLOOKUP(B162,Absen!$A$1:$C$501,2,FALSE),"No") -> No | M162: =IF(L162="no",K162,K162-10)*10% -> 7.9 | N162: =SUM(E162*12.5%,F162*12.5%,H162*12.5%,I162*12.5%,G162*20%,J162*20%,M162) -> 60.925 | O162: =VLOOKUP(N162,Helper!$B$30:$C$35,2,TRUE) -> C | P162: =INDEX(Detail!$A$1:$A$1001,MATCH(B162,Detail!$G$1:$G$1001,0)) -> 37860 | Q162: =INDEX(Detail!$F$1:$F$1001,MATCH(Main!B162,Detail!$G$1:$G$1001,0)) -> Binjai | R162: =INDEX(Detail!$C$1:$C$1001,MATCH(B162,Detail!$G$1:$G$1001,0),1) -> 158 | S162: =INDEX(Detail!$D$1:$D$1001,MATCH(B162,Detail!$G$1:$G$1001,0),1) -> 70 | T162: =INDEX(Detail!$E$1:$E$1001,MATCH(Main!B162,Detail!$G$1:$G$1001,0)) -> Jalan Waringin No. 1 | U162: =INDEX(Detail!$B$1:$B$1001,MATCH(B162,Detail!$G$1:$G$1001,0),1) -> A+ | V162: {=INDEX(Dosen!$B$3:$E$8,MATCH(Main!C162,Dosen!$A$3:$A$8,0),IF(AND(Main!A162>=1,Main!A162<=250),1,IF(AND(Main!A162>=251,Main!A162<=500),2,IF(AND(Main!A162>=501,Main!A162<=750),3,4))))} -> Pak Krisna | W162: =_xlfn.XLOOKUP(B162,Detail!$G$1:$G$1001,Detail!$B$1:$B$1001) -> A+
A163: 12 | B163: =CONCATENATE("B",TEXT(A163,"0000")) -> B0012 | C163: Fisika | D163: =VLOOKUP(B163,Detail!$G$1:$H$1001,2,FALSE) -> Jatmiko Halimah | E163: 89 | F163: 66 | G163: 58 | H163: 56 | I163: 72 | J163: 40 | K163: 66 | L163: =IFERROR(VLOOKUP(B163,Absen!$A$1:$C$501,2,FALSE),"No") -> 44826 | M163: =IF(L163="no",K163,K163-10)*10% -> 5.6 | N163: =SUM(E163*12.5%,F163*12.5%,H163*12.5%,I163*12.5%,G163*20%,J163*20%,M163) -> 60.575 | O163: =VLOOKUP(N163,Helper!$B$30:$C$35,2,TRUE) -> C | P163: =INDEX(Detail!$A$1:$A$1001,MATCH(B163,Detail!$G$1:$G$1001,0)) -> 37738 | Q163: =INDEX(Detail!$F$1:$F$1001,MATCH(Main!B163,Detail!$G$1:$G$1001,0)) -> Pekalongan | R163: =INDEX(Detail!$C$1:$C$1001,MATCH(B163,Detail!$G$1:$G$1001,0),1) -> 167 | S163: =INDEX(Detail!$D$1:$D$1001,MATCH(B163,Detail!$G$1:$G$1001,0),1) -> 78 | T163: =INDEX(Detail!$E$1:$E$1001,MATCH(Main!B163,Detail!$G$1:$G$1001,0)) -> Jl. Kutai No. 34 | U163: =INDEX(Detail!$B$1:$B$1001,MATCH(B163,Detail!$G$1:$G$1001,0),1) -> AB- | V163: {=INDEX(Dosen!$B$3:$E$8,MATCH(Main!C163,Dosen!$A$3:$A$8,0),IF(AND(Main!A163>=1,Main!A163<=250),1,IF(AND(Main!A163>=251,Main!A163<=500),2,IF(AND(Main!A163>=501,Main!A163<=750),3,4))))} -> Pak Krisna | W163: =_xlfn.XLOOKUP(B163,Detail!$G$1:$G$1001,Detail!$B$1:$B$1001) -> AB-
A164: 23 | B164: =CONCATENATE("B",TEXT(A164,"0000")) -> B0023 | C164: Fisika | D164: =VLOOKUP(B164,Detail!$G$1:$H$1001,2,FALSE) -> Wakiman Prastuti | E164: 84 | F164: 49 | G164: 87 | H164: 56 | I164: 64 | J164: 60 | K164: 73 | L164: =IFERROR(VLOOKUP(B164,Absen!$A$1:$C$501,2,FALSE),"No") -> No | M164: =IF(L164="no",K164,K164-10)*10% -> 7.3 | N164: =SUM(E164*12.5%,F164*12.5%,H164*12.5%,I164*12.5%,G164*20%,J164*20%,M164) -> 68.325 | O164: =VLOOKUP(N164,Helper!$B$30:$C$35,2,TRUE) -> C | P164: =INDEX(Detail!$A$1:$A$1001,MATCH(B164,Detail!$G$1:$G$1001,0)) -> 38066 | Q164: =INDEX(Detail!$F$1:$F$1001,MATCH(Main!B164,Detail!$G$1:$G$1001,0)) -> Batu | R164: =INDEX(Detail!$C$1:$C$1001,MATCH(B164,Detail!$G$1:$G$1001,0),1) -> 166 | S164: =INDEX(Detail!$D$1:$D$1001,MATCH(B164,Detail!$G$1:$G$1001,0),1) -> 50 | T164: =INDEX(Detail!$E$1:$E$1001,MATCH(Main!B164,Detail!$G$1:$G$1001,0)) -> Jl. PHH. Mustofa No. 9 | U164: =INDEX(Detail!$B$1:$B$1001,MATCH(B164,Detail!$G$1:$G$1001,0),1) -> O- | V164: {=INDEX(Dosen!$B$3:$E$8,MATCH(Main!C164,Dosen!$A$3:$A$8,0),IF(AND(Main!A164>=1,Main!A164<=250),1,IF(AND(Main!A164>=251,Main!A164<=500),2,IF(AND(Main!A164>=501,Main!A164<=750),3,4))))} -> Pak Krisna | W164: =_xlfn.XLOOKUP(B164,Detail!$G$1:$G$1001,Detail!$B$1:$B$1001) -> O-
A165: 35 | B165: =CONCATENATE("B",TEXT(A165,"0000")) -> B0035 | C165: Fisika | D165: =VLOOKUP(B165,Detail!$G$1:$H$1001,2,FALSE) -> Embuh Adriansyah | E165: 70 | F165: 53 | G165: 88 | H165: 67 | I165: 75 | J165: 60 | K165: 63 | L165: =IFERROR(VLOOKUP(B165,Absen!$A$1:$C$501,2,FALSE),"No") -> 44789 | M165: =IF(L165="no",K165,K165-10)*10% -> 5.3 | N165: =SUM(E165*12.5%,F165*12.5%,H165*12.5%,I165*12.5%,G165*20%,J165*20%,M165) -> 68.025 | O165: =VLOOKUP(N165,Helper!$B$30:$C$35,2,TRUE) -> C | P165: =INDEX(Detail!$A$1:$A$1001,MATCH(B165,Detail!$G$1:$G$1001,0)) -> 37906 | Q165: =INDEX(Detail!$F$1:$F$1001,MATCH(Main!B165,Detail!$G$1:$G$1001,0)) -> Bitung | R165: =INDEX(Detail!$C$1:$C$1001,MATCH(B165,Detail!$G$1:$G$1001,0),1) -> 171 | S165: =INDEX(Detail!$D$1:$D$1001,MATCH(B165,Detail!$G$1:$G$1001,0),1) -> 67 | T165: =INDEX(Detail!$E$1:$E$1001,MATCH(Main!B165,Detail!$G$1:$G$1001,0)) -> Gang Otto Iskandardinata No. 06 | U165: =INDEX(Detail!$B$1:$B$1001,MATCH(B165,Detail!$G$1:$G$1001,0),1) -> O+ | V165: {=INDEX(Dosen!$B$3:$E$8,MATCH(Main!C165,Dosen!$A$3:$A$8,0),IF(AND(Main!A165>=1,Main!A165<=250),1,IF(AND(Main!A165>=251,Main!A165<=500),2,IF(AND(Main!A165>=501,Main!A165<=750),3,4))))} -> Pak Krisna | W165: =_xlfn.XLOOKUP(B165,Detail!$G$1:$G$1001,Detail!$B$1:$B$1001) -> O+
A166: 37 | B166: =CONCATENATE("B",TEXT(A166,"0000")) -> B0037 | C166: Fisika | D166: =VLOOKUP(B166,Detail!$G$1:$H$1001,2,FALSE) -> Hendra Pratama | E166: 72 | F166: 54 | G166: 55 | H166: 58 | I166: 72 | J166: 73 | K166: 82 | L166: =IFERROR(VLOOKUP(B166,Absen!$A$1:$C$501,2,FALSE),"No") -> No | M166: =IF(L166="no",K166,K166-10)*10% -> 8.2 | N166: =SUM(E166*12.5%,F166*12.5%,H166*12.5%,I166*12.5%,G166*20%,J166*20%,M166) -> 65.8 | O166: =VLOOKUP(N166,Helper!$B$30:$C$35,2,TRUE) -> C | P166: =INDEX(Detail!$A$1:$A$1001,MATCH(B166,Detail!$G$1:$G$1001,0)) -> 37192 | Q166: =INDEX(Detail!$F$1:$F$1001,MATCH(Main!B166,Detail!$G$1:$G$1001,0)) -> Tual | R166: =INDEX(Detail!$C$1:$C$1001,MATCH(B166,Detail!$G$1:$G$1001,0),1) -> 174 | S166: =INDEX(Detail!$D$1:$D$1001,MATCH(B166,Detail!$G$1:$G$1001,0),1) -> 57 | T166: =INDEX(Detail!$E$1:$E$1001,MATCH(Main!B166,Detail!$G$1:$G$1001,0)) -> Gg. Ahmad Dahlan No. 15 | U166: =INDEX(Detail!$B$1:$B$1001,MATCH(B166,Detail!$G$1:$G$1001,0),1) -> A+ | V166: {=INDEX(Dosen!$B$3:$E$8,MATCH(Main!C166,Dosen!$A$3:$A$8,0),IF(AND(Main!A166>=1,Main!A166<=250),1,IF(AND(Main!A166>=251,Main!A166<=500),2,IF(AND(Main!A166>=501,Main!A166<=750),3,4))))} -> Pak Krisna | W166: =_xlfn.XLOOKUP(B166,Detail!$G$1:$G$1001,Detail!$B$1:$B$1001) -> A+
A167: 42 | B167: =CONCATENATE("B",TEXT(A167,"0000")) -> B0042 | C167: Fisika | D167: =VLOOKUP(B167,Detail!$G$1:$H$1001,2,FALSE) -> Darijan Zulkarnain | E167: 78 | F167: 52 | G167: 94 | H167: 69 | I167: 86 | J167: 68 | K167: 89 | L167: =IFERROR(VLOOKUP(B167,Absen!$A$1:$C$501,2,FALSE),"No") -> No | M167: =IF(L167="no",K167,K167-10)*10% -> 8.9 | N167: =SUM(E167*12.5%,F167*12.5%,H167*12.5%,I167*12.5%,G167*20%,J167*20%,M167) -> 76.925 | O167: =VLOOKUP(N167,Helper!$B$30:$C$35,2,TRUE) -> B | P167: =INDEX(Detail!$A$1:$A$1001,MATCH(B167,Detail!$G$1:$G$1001,0)) -> 38412 | Q167: =INDEX(Detail!$F$1:$F$1001,MATCH(Main!B167,Detail!$G$1:$G$1001,0)) -> Balikpapan | R167: =INDEX(Detail!$C$1:$C$1001,MATCH(B167,Detail!$G$1:$G$1001,0),1) -> 150 | S167: =INDEX(Detail!$D$1:$D$1001,MATCH(B167,Detail!$G$1:$G$1001,0),1) -> 85 | T167: =INDEX(Detail!$E$1:$E$1001,MATCH(Main!B167,Detail!$G$1:$G$1001,0)) -> Gang Surapati No. 95 | U167: =INDEX(Detail!$B$1:$B$1001,MATCH(B167,Detail!$G$1:$G$1001,0),1) -> A+ | V167: {=INDEX(Dosen!$B$3:$E$8,MATCH(Main!C167,Dosen!$A$3:$A$8,0),IF(AND(Main!A167>=1,Main!A167<=250),1,IF(AND(Main!A167>=251,Main!A167<=500),2,IF(AND(Main!A167>=501,Main!A167<=750),3,4))))} -> Pak Krisna | W167: =_xlfn.XLOOKUP(B167,Detail!$G$1:$G$1001,Detail!$B$1:$B$1001) -> A+
A168: 48 | B168: =CONCATENATE("B",TEXT(A168,"0000")) -> B0048 | C168: Fisika | D168: =VLOOKUP(B168,Detail!$G$1:$H$1001,2,FALSE) -> Pandu Laksmiwati | E168: 77 | F168: 49 | G168: 40 | H168: 67 | I168: 77 | J168: 62 | K168: 89 | L168: =IFERROR(VLOOKUP(B168,Absen!$A$1:$C$501,2,FALSE),"No") -> No | M168: =IF(L168="no",K168,K168-10)*10% -> 8.9 | N168: =SUM(E168*12.5%,F168*12.5%,H168*12.5%,I168*12.5%,G168*20%,J168*20%,M168) -> 63.05 | O168: =VLOOKUP(N168,Helper!$B$30:$C$35,2,TRUE) -> C | P168: =INDEX(Detail!$A$1:$A$1001,MATCH(B168,Detail!$G$1:$G$1001,0)) -> 37255 | Q168: =INDEX(Detail!$F$1:$F$1001,MATCH(Main!B168,Detail!$G$1:$G$1001,0)) -> Bau-Bau | R168: =INDEX(Detail!$C$1:$C$1001,MATCH(B168,Detail!$G$1:$G$1001,0),1) -> 159 | S168: =INDEX(Detail!$D$1:$D$1001,MATCH(B168,Detail!$G$1:$G$1001,0),1) -> 56 | T168: =INDEX(Detail!$E$1:$E$1001,MATCH(Main!B168,Detail!$G$1:$G$1001,0)) -> Gg. Abdul Muis No. 9 | U168: =INDEX(Detail!$B$1:$B$1001,MATCH(B168,Detail!$G$1:$G$1001,0),1) -> O+ | V168: {=INDEX(Dosen!$B$3:$E$8,MATCH(Main!C168,Dosen!$A$3:$A$8,0),IF(AND(Main!A168>=1,Main!A168<=250),1,IF(AND(Main!A168>=251,Main!A168<=500),2,IF(AND(Main!A168>=501,Main!A168<=750),3,4))))} -> Pak Krisna | W168: =_xlfn.XLOOKUP(B168,Detail!$G$1:$G$1001,Detail!$B$1:$B$1001) -> O+
A169: 56 | B169: =CONCATENATE("B",TEXT(A169,"0000")) -> B0056 | C169: Fisika | D169: =VLOOKUP(B169,Detail!$G$1:$H$1001,2,FALSE) -> Hartana Astuti | E169: 59 | F169: 44 | G169: 81 | H169: 69 | I169: 57 | J169: 44 | K169: 91 | L169: =IFERROR(VLOOKUP(B169,Absen!$A$1:$C$501,2,FALSE),"No") -> 44767 | M169: =IF(L169="no",K169,K169-10)*10% -> 8.1 | N169: =SUM(E169*12.5%,F169*12.5%,H169*12.5%,I169*12.5%,G169*20%,J169*20%,M169) -> 61.725 | O169: =VLOOKUP(N169,Helper!$B$30:$C$35,2,TRUE) -> C | P169: =INDEX(Detail!$A$1:$A$1001,MATCH(B169,Detail!$G$1:$G$1001,0)) -> 37336 | Q169: =INDEX(Detail!$F$1:$F$1001,MATCH(Main!B169,Detail!$G$1:$G$1001,0)) -> Tarakan | R169: =INDEX(Detail!$C$1:$C$1001,MATCH(B169,Detail!$G$1:$G$1001,0),1) -> 168 | S169: =INDEX(Detail!$D$1:$D$1001,MATCH(B169,Detail!$G$1:$G$1001,0),1) -> 51 | T169: =INDEX(Detail!$E$1:$E$1001,MATCH(Main!B169,Detail!$G$1:$G$1001,0)) -> Gang Ronggowarsito No. 37 | U169: =INDEX(Detail!$B$1:$B$1001,MATCH(B169,Detail!$G$1:$G$1001,0),1) -> A- | V169: {=INDEX(Dosen!$B$3:$E$8,MATCH(Main!C169,Dosen!$A$3:$A$8,0),IF(AND(Main!A169>=1,Main!A169<=250),1,IF(AND(Main!A169>=251,Main!A169<=500),2,IF(AND(Main!A169>=501,Main!A169<=750),3,4))))} -> Pak Krisna | W169: =_xlfn.XLOOKUP(B169,Detail!$G$1:$G$1001,Detail!$B$1:$B$1001) -> A-
A170: 66 | B170: =CONCATENATE("B",TEXT(A170,"0000")) -> B0066 | C170: Fisika | D170: =VLOOKUP(B170,Detail!$G$1:$H$1001,2,FALSE) -> Arsipatra Lailasari | E170: 57 | F170: 46 | G170: 44 | H170: 70 | I170: 57 | J170: 88 | K170: 88 | L170: =IFERROR(VLOOKUP(B170,Absen!$A$1:$C$501,2,FALSE),"No") -> 44835 | M170: =IF(L170="no",K170,K170-10)*10% -> 7.8 | N170: =SUM(E170*12.5%,F170*12.5%,H170*12.5%,I170*12.5%,G170*20%,J170*20%,M170) -> 62.95 | O170: =VLOOKUP(N170,Helper!$B$30:$C$35,2,TRUE) -> C | P170: =INDEX(Detail!$A$1:$A$1001,MATCH(B170,Detail!$G$1:$G$1001,0)) -> 38283 | Q170: =INDEX(Detail!$F$1:$F$1001,MATCH(Main!B170,Detail!$G$1:$G$1001,0)) -> Batam | R170: =INDEX(Detail!$C$1:$C$1001,MATCH(B170,Detail!$G$1:$G$1001,0),1) -> 180 | S170: =INDEX(Detail!$D$1:$D$1001,MATCH(B170,Detail!$G$1:$G$1001,0),1) -> 76 | T170: =INDEX(Detail!$E$1:$E$1001,MATCH(Main!B170,Detail!$G$1:$G$1001,0)) -> Jl. Kutisari Selatan No. 43 | U170: =INDEX(Detail!$B$1:$B$1001,MATCH(B170,Detail!$G$1:$G$1001,0),1) -> A- | V170: {=INDEX(Dosen!$B$3:$E$8,MATCH(Main!C170,Dosen!$A$3:$A$8,0),IF(AND(Main!A170>=1,Main!A170<=250),1,IF(AND(Main!A170>=251,Main!A170<=500),2,IF(AND(Main!A170>=501,Main!A170<=750),3,4))))} -> Pak Krisna | W170: =_xlfn.XLOOKUP(B170,Detail!$G$1:$G$1001,Detail!$B$1:$B$1001) -> A-
A171: 76 | B171: =CONCATENATE("B",TEXT(A171,"0000")) -> B0076 | C171: Fisika | D171: =VLOOKUP(B171,Detail!$G$1:$H$1001,2,FALSE) -> Paulin Hariyah | E171: 54 | F171: 74 | G171: 52 | H171: 60 | I171: 89 | J171: 93 | K171: 69 | L171: =IFERROR(VLOOKUP(B171,Absen!$A$1:$C$501,2,FALSE),"No") -> No | M171: =IF(L171="no",K171,K171-10)*10% -> 6.9 | N171: =SUM(E171*12.5%,F171*12.5%,H171*12.5%,I171*12.5%,G171*20%,J171*20%,M171) -> 70.525 | O171: =VLOOKUP(N171,Helper!$B$30:$C$35,2,TRUE) -> B | P171: =INDEX(Detail!$A$1:$A$1001,MATCH(B171,Detail!$G$1:$G$1001,0)) -> 38067 | Q171: =INDEX(Detail!$F$1:$F$1001,MATCH(Main!B171,Detail!$G$1:$G$1001,0)) -> Tidore Kepulauan | R171: =INDEX(Detail!$C$1:$C$1001,MATCH(B171,Detail!$G$1:$G$1001,0),1) -> 151 | S171: =INDEX(Detail!$D$1:$D$1001,MATCH(B171,Detail!$G$1:$G$1001,0),1) -> 93 | T171: =INDEX(Detail!$E$1:$E$1001,MATCH(Main!B171,Detail!$G$1:$G$1001,0)) -> Gg. Peta No. 50 | U171: =INDEX(Detail!$B$1:$B$1001,MATCH(B171,Detail!$G$1:$G$1001,0),1) -> AB+ | V171: {=INDEX(Dosen!$B$3:$E$8,MATCH(Main!C171,Dosen!$A$3:$A$8,0),IF(AND(Main!A171>=1,Main!A171<=250),1,IF(AND(Main!A171>=251,Main!A171<=500),2,IF(AND(Main!A171>=501,Main!A171<=750),3,4))))} -> Pak Krisna | W171: =_xlfn.XLOOKUP(B171,Detail!$G$1:$G$1001,Detail!$B$1:$B$1001) -> AB+
A172: 79 | B172: =CONCATENATE("B",TEXT(A172,"0000")) -> B0079 | C172: Fisika | D172: =VLOOKUP(B172,Detail!$G$1:$H$1001,2,FALSE) -> Edi Nashiruddin | E172: 63 | F172: 49 | G172: 55 | H172: 65 | I172: 67 | J172: 44 | K172: 66 | L172: =IFERROR(VLOOKUP(B172,Absen!$A$1:$C$501,2,FALSE),"No") -> No | M172: =IF(L172="no",K172,K172-10)*10% -> 6.6 | N172: =SUM(E172*12.5%,F172*12.5%,H172*12.5%,I172*12.5%,G172*20%,J172*20%,M172) -> 56.9 | O172: =VLOOKUP(N172,Helper!$B$30:$C$35,2,TRUE) -> D | P172: =INDEX(Detail!$A$1:$A$1001,MATCH(B172,Detail!$G$1:$G$1001,0)) -> 37433 | Q172: =INDEX(Detail!$F$1:$F$1001,MATCH(Main!B172,Detail!$G$1:$G$1001,0)) -> Denpasar | R172: =INDEX(Detail!$C$1:$C$1001,MATCH(B172,Detail!$G$1:$G$1001,0),1) -> 166 | S172: =INDEX(Detail!$D$1:$D$1001,MATCH(B172,Detail!$G$1:$G$1001,0),1) -> 67 | T172: =INDEX(Detail!$E$1:$E$1001,MATCH(Main!B172,Detail!$G$1:$G$1001,0)) -> Jalan Dr. Djunjunan No. 3 | U172: =INDEX(Detail!$B$1:$B$1001,MATCH(B172,Detail!$G$1:$G$1001,0),1) -> O+ | V172: {=INDEX(Dosen!$B$3:$E$8,MATCH(Main!C172,Dosen!$A$3:$A$8,0),IF(AND(Main!A172>=1,Main!A172<=250),1,IF(AND(Main!A172>=251,Main!A172<=500),2,IF(AND(Main!A172>=501,Main!A172<=750),3,4))))} -> Pak Krisna | W172: =_xlfn.XLOOKUP(B172,Detail!$G$1:$G$1001,Detail!$B$1:$B$1001) -> O+
... A320: 993 | B320: =CONCATENATE("B",TEXT(A320,"0000")) -> B0993 | C320: Fisika | D320: =VLOOKUP(B320,Detail!$G$1:$H$1001,2,FALSE) -> Novi Prabowo | E320: 89 | F320: 63 | G320: 66 | H320: 55 | I320: 95 | J320: 75 | K320: 93 | L320: =IFERROR(VLOOKUP(B320,Absen!$A$1:$C$501,2,FALSE),"No") -> 44810 | M320: =IF(L320="no",K320,K320-10)*10% -> 8.3 | N320: =SUM(E320*12.5%,F320*12.5%,H320*12.5%,I320*12.5%,G320*20%,J320*20%,M320) -> 74.25 | O320: =VLOOKUP(N320,Helper!$B$30:$C$35,2,TRUE) -> B | P320: =INDEX(Detail!$A$1:$A$1001,MATCH(B320,Detail!$G$1:$G$1001,0)) -> 38204 | Q320: =INDEX(Detail!$F$1:$F$1001,MATCH(Main!B320,Detail!$G$1:$G$1001,0)) -> Pariaman | R320: =INDEX(Detail!$C$1:$C$1001,MATCH(B320,Detail!$G$1:$G$1001,0),1) -> 157 | S320: =INDEX(Detail!$D$1:$D$1001,MATCH(B320,Detail!$G$1:$G$1001,0),1) -> 51 | T320: =INDEX(Detail!$E$1:$E$1001,MATCH(Main!B320,Detail!$G$1:$G$1001,0)) -> Gang Cihampelas No. 1 | U320: =INDEX(Detail!$B$1:$B$1001,MATCH(B320,Detail!$G$1:$G$1001,0),1) -> A- | V320: {=INDEX(Dosen!$B$3:$E$8,MATCH(Main!C320,Dosen!$A$3:$A$8,0),IF(AND(Main!A320>=1,Main!A320<=250),1,IF(AND(Main!A320>=251,Main!A320<=500),2,IF(AND(Main!A320>=501,Main!A320<=750),3,4))))} -> Pak Budi | W320: =_xlfn.XLOOKUP(B320,Detail!$G$1:$G$1001,Detail!$B$1:$B$1001) -> A-
A321: 19 | B321: =CONCATENATE("C",TEXT(A321,"0000")) -> C0019 | C321: Kimia | D321: =VLOOKUP(B321,Detail!$G$1:$H$1001,2,FALSE) -> Daniswara Manullang | E321: 85 | F321: 63 | G321: 93 | H321: 65 | I321: 84 | J321: 48 | K321: 89 | L321: =IFERROR(VLOOKUP(B321,Absen!$A$1:$C$501,2,FALSE),"No") -> 44846 | M321: =IF(L321="no",K321,K321-10)*10% -> 7.9 | N321: =SUM(E321*12.5%,F321*12.5%,H321*12.5%,I321*12.5%,G321*20%,J321*20%,M321) -> 73.225 | O321: =VLOOKUP(N321,Helper!$B$30:$C$35,2,TRUE) -> B | P321: =INDEX(Detail!$A$1:$A$1001,MATCH(B321,Detail!$G$1:$G$1001,0)) -> 38185 | Q321: =INDEX(Detail!$F$1:$F$1001,MATCH(Main!B321,Detail!$G$1:$G$1001,0)) -> Banda Aceh | R321: =INDEX(Detail!$C$1:$C$1001,MATCH(B321,Detail!$G$1:$G$1001,0),1) -> 161 | S321: =INDEX(Detail!$D$1:$D$1001,MATCH(B321,Detail!$G$1:$G$1001,0),1) -> 89 | T321: =INDEX(Detail!$E$1:$E$1001,MATCH(Main!B321,Detail!$G$1:$G$1001,0)) -> Jalan Dipenogoro No. 70 | U321: =INDEX(Detail!$B$1:$B$1001,MATCH(B321,Detail!$G$1:$G$1001,0),1) -> AB+ | V321: {=INDEX(Dosen!$B$3:$E$8,MATCH(Main!C321,Dosen!$A$3:$A$8,0),IF(AND(Main!A321>=1,Main!A321<=250),1,IF(AND(Main!A321>=251,Main!A321<=500),2,IF(AND(Main!A321>=501,Main!A321<=750),3,4))))} -> Pak Budi | W321: =_xlfn.XLOOKUP(B321,Detail!$G$1:$G$1001,Detail!$B$1:$B$1001) -> AB+
A322: 29 | B322: =CONCATENATE("C",TEXT(A322,"0000")) -> C0029 | C322: Kimia | D322: =VLOOKUP(B322,Detail!$G$1:$H$1001,2,FALSE) -> Banawi Laksita | E322: 72 | F322: 51 | G322: 43 | H322: 74 | I322: 56 | J322: 50 | K322: 79 | L322: =IFERROR(VLOOKUP(B322,Absen!$A$1:$C$501,2,FALSE),"No") -> 44772 | M322: =IF(L322="no",K322,K322-10)*10% -> 6.9 | N322: =SUM(E322*12.5%,F322*12.5%,H322*12.5%,I322*12.5%,G322*20%,J322*20%,M322) -> 57.125 | O322: =VLOOKUP(N322,Helper!$B$30:$C$35,2,TRUE) -> D | P322: =INDEX(Detail!$A$1:$A$1001,MATCH(B322,Detail!$G$1:$G$1001,0)) -> 37209 | Q322: =INDEX(Detail!$F$1:$F$1001,MATCH(Main!B322,Detail!$G$1:$G$1001,0)) -> Langsa | R322: =INDEX(Detail!$C$1:$C$1001,MATCH(B322,Detail!$G$1:$G$1001,0),1) -> 150 | S322: =INDEX(Detail!$D$1:$D$1001,MATCH(B322,Detail!$G$1:$G$1001,0),1) -> 82 | T322: =INDEX(Detail!$E$1:$E$1001,MATCH(Main!B322,Detail!$G$1:$G$1001,0)) -> Gang Rajawali Timur No. 4 | U322: =INDEX(Detail!$B$1:$B$1001,MATCH(B322,Detail!$G$1:$G$1001,0),1) -> A- | V322: {=INDEX(Dosen!$B$3:$E$8,MATCH(Main!C322,Dosen!$A$3:$A$8,0),IF(AND(Main!A322>=1,Main!A322<=250),1,IF(AND(Main!A322>=251,Main!A322<=500),2,IF(AND(Main!A322>=501,Main!A322<=750),3,4))))} -> Pak Budi | W322: =_xlfn.XLOOKUP(B322,Detail!$G$1:$G$1001,Detail!$B$1:$B$1001) -> A-
A323: 30 | B323: =CONCATENATE("C",TEXT(A323,"0000")) -> C0030 | C323: Kimia | D323: =VLOOKUP(B323,Detail!$G$1:$H$1001,2,FALSE) -> Dewi Budiman | E323: 59 | F323: 46 | G323: 87 | H323: 71 | I323: 57 | J323: 48 | K323: 71 | L323: =IFERROR(VLOOKUP(B323,Absen!$A$1:$C$501,2,FALSE),"No") -> 44883 | M323: =IF(L323="no",K323,K323-10)*10% -> 6.1 | N323: =SUM(E323*12.5%,F323*12.5%,H323*12.5%,I323*12.5%,G323*20%,J323*20%,M323) -> 62.225 | O323: =VLOOKUP(N323,Helper!$B$30:$C$35,2,TRUE) -> C | P323: =INDEX(Detail!$A$1:$A$1001,MATCH(B323,Detail!$G$1:$G$1001,0)) -> 38444 | Q323: =INDEX(Detail!$F$1:$F$1001,MATCH(Main!B323,Detail!$G$1:$G$1001,0)) -> Samarinda | R323: =INDEX(Detail!$C$1:$C$1001,MATCH(B323,Detail!$G$1:$G$1001,0),1) -> 180 | S323: =INDEX(Detail!$D$1:$D$1001,MATCH(B323,Detail!$G$1:$G$1001,0),1) -> 86 | T323: =INDEX(Detail!$E$1:$E$1001,MATCH(Main!B323,Detail!$G$1:$G$1001,0)) -> Jl. Medokan Ayu No. 73 | U323: =INDEX(Detail!$B$1:$B$1001,MATCH(B323,Detail!$G$1:$G$1001,0),1) -> A- | V323: {=INDEX(Dosen!$B$3:$E$8,MATCH(Main!C323,Dosen!$A$3:$A$8,0),IF(AND(Main!A323>=1,Main!A323<=250),1,IF(AND(Main!A323>=251,Main!A323<=500),2,IF(AND(Main!A323>=501,Main!A323<=750),3,4))))} -> Pak Budi | W323: =_xlfn.XLOOKUP(B323,Detail!$G$1:$G$1001,Detail!$B$1:$B$1001) -> A-
A324: 49 | B324: =CONCATENATE("C",TEXT(A324,"0000")) -> C0049 | C324: Kimia | D324: =VLOOKUP(B324,Detail!$G$1:$H$1001,2,FALSE) -> Cecep Mansur | E324: 51 | F324: 62 | G324: 51 | H324: 54 | I324: 68 | J324: 100 | K324: 82 | L324: =IFERROR(VLOOKUP(B324,Absen!$A$1:$C$501,2,FALSE),"No") -> No | M324: =IF(L324="no",K324,K324-10)*10% -> 8.2 | N324: =SUM(E324*12.5%,F324*12.5%,H324*12.5%,I324*12.5%,G324*20%,J324*20%,M324) -> 67.775 | O324: =VLOOKUP(N324,Helper!$B$30:$C$35,2,TRUE) -> C | P324: =INDEX(Detail!$A$1:$A$1001,MATCH(B324,Detail!$G$1:$G$1001,0)) -> 37102 | Q324: =INDEX(Detail!$F$1:$F$1001,MATCH(Main!B324,Detail!$G$1:$G$1001,0)) -> Magelang | R324: =INDEX(Detail!$C$1:$C$1001,MATCH(B324,Detail!$G$1:$G$1001,0),1) -> 180 | S324: =INDEX(Detail!$D$1:$D$1001,MATCH(B324,Detail!$G$1:$G$1001,0),1) -> 56 | T324: =INDEX(Detail!$E$1:$E$1001,MATCH(Main!B324,Detail!$G$1:$G$1001,0)) -> Jl. Indragiri No. 50 | U324: =INDEX(Detail!$B$1:$B$1001,MATCH(B324,Detail!$G$1:$G$1001,0),1) -> A+ | V324: {=INDEX(Dosen!$B$3:$E$8,MATCH(Main!C324,Dosen!$A$3:$A$8,0),IF(AND(Main!A324>=1,Main!A324<=250),1,IF(AND(Main!A324>=251,Main!A324<=500),2,IF(AND(Main!A324>=501,Main!A324<=750),3,4))))} -> Pak Budi | W324: =_xlfn.XLOOKUP(B324,Detail!$G$1:$G$1001,Detail!$B$1:$B$1001) -> A+
A325: 54 | B325: =CONCATENATE("C",TEXT(A325,"0000")) -> C0054 | C325: Kimia | D325: =VLOOKUP(B325,Detail!$G$1:$H$1001,2,FALSE) -> Radika Aryani | E325: 77 | F325: 69 | G325: 61 | H325: 73 | I325: 52 | J325: 99 | K325: 91 | L325: =IFERROR(VLOOKUP(B325,Absen!$A$1:$C$501,2,FALSE),"No") -> 44847 | M325: =IF(L325="no",K325,K325-10)*10% -> 8.1 | N325: =SUM(E325*12.5%,F325*12.5%,H325*12.5%,I325*12.5%,G325*20%,J325*20%,M325) -> 73.975 | O325: =VLOOKUP(N325,Helper!$B$30:$C$35,2,TRUE) -> B | P325: =INDEX(Detail!$A$1:$A$1001,MATCH(B325,Detail!$G$1:$G$1001,0)) -> 37113 | Q325: =INDEX(Detail!$F$1:$F$1001,MATCH(Main!B325,Detail!$G$1:$G$1001,0)) -> Cimahi | R325: =INDEX(Detail!$C$1:$C$1001,MATCH(B325,Detail!$G$1:$G$1001,0),1) -> 179 | S325: =INDEX(Detail!$D$1:$D$1001,MATCH(B325,Detail!$G$1:$G$1001,0),1) -> 57 | T325: =INDEX(Detail!$E$1:$E$1001,MATCH(Main!B325,Detail!$G$1:$G$1001,0)) -> Jl. Suniaraja No. 5 | U325: =INDEX(Detail!$B$1:$B$1001,MATCH(B325,Detail!$G$1:$G$1001,0),1) -> O- | V325: {=INDEX(Dosen!$B$3:$E$8,MATCH(Main!C325,Dosen!$A$3:$A$8,0),IF(AND(Main!A325>=1,Main!A325<=250),1,IF(AND(Main!A325>=251,Main!A325<=500),2,IF(AND(Main!A325>=501,Main!A325<=750),3,4))))} -> Pak Budi | W325: =_xlfn.XLOOKUP(B325,Detail!$G$1:$G$1001,Detail!$B$1:$B$1001) -> O-
A326: 55 | B326: =CONCATENATE("C",TEXT(A326,"0000")) -> C0055 | C326: Kimia | D326: =VLOOKUP(B326,Detail!$G$1:$H$1001,2,FALSE) -> Warji Wahyudin | E326: 68 | F326: 72 | G326: 58 | H326: 64 | I326: 56 | J326: 42 | K326: 74 | L326: =IFERROR(VLOOKUP(B326,Absen!$A$1:$C$501,2,FALSE),"No") -> No | M326: =IF(L326="no",K326,K326-10)*10% -> 7.4 | N326: =SUM(E326*12.5%,F326*12.5%,H326*12.5%,I326*12.5%,G326*20%,J326*20%,M326) -> 59.9 | O326: =VLOOKUP(N326,Helper!$B$30:$C$35,2,TRUE) -> D | P326: =INDEX(Detail!$A$1:$A$1001,MATCH(B326,Detail!$G$1:$G$1001,0)) -> 38369 | Q326: =INDEX(Detail!$F$1:$F$1001,MATCH(Main!B326,Detail!$G$1:$G$1001,0)) -> Lhokseumawe | R326: =INDEX(Detail!$C$1:$C$1001,MATCH(B326,Detail!$G$1:$G$1001,0),1) -> 155 | S326: =INDEX(Detail!$D$1:$D$1001,MATCH(B326,Detail!$G$1:$G$1001,0),1) -> 73 | T326: =INDEX(Detail!$E$1:$E$1001,MATCH(Main!B326,Detail!$G$1:$G$1001,0)) -> Jalan Kebonjati No. 08 | U326: =INDEX(Detail!$B$1:$B$1001,MATCH(B326,Detail!$G$1:$G$1001,0),1) -> B- | V326: {=INDEX(Dosen!$B$3:$E$8,MATCH(Main!C326,Dosen!$A$3:$A$8,0),IF(AND(Main!A326>=1,Main!A326<=250),1,IF(AND(Main!A326>=251,Main!A326<=500),2,IF(AND(Main!A326>=501,Main!A326<=750),3,4))))} -> Pak Budi | W326: =_xlfn.XLOOKUP(B326,Detail!$G$1:$G$1001,Detail!$B$1:$B$1001) -> B-
A327: 64 | B327: =CONCATENATE("C",TEXT(A327,"0000")) -> C0064 | C327: Kimia | D327: =VLOOKUP(B327,Detail!$G$1:$H$1001,2,FALSE) -> Gantar Sihombing | E327: 68 | F327: 53 | G327: 87 | H327: 55 | I327: 91 | J327: 78 | K327: 90 | L327: =IFERROR(VLOOKUP(B327,Absen!$A$1:$C$501,2,FALSE),"No") -> 44887 | M327: =IF(L327="no",K327,K327-10)*10% -> 8 | N327: =SUM(E327*12.5%,F327*12.5%,H327*12.5%,I327*12.5%,G327*20%,J327*20%,M327) -> 74.375 | O327: =VLOOKUP(N327,Helper!$B$30:$C$35,2,TRUE) -> B | P327: =INDEX(Detail!$A$1:$A$1001,MATCH(B327,Detail!$G$1:$G$1001,0)) -> 37710 | Q327: =INDEX(Detail!$F$1:$F$1001,MATCH(Main!B327,Detail!$G$1:$G$1001,0)) -> Pasuruan | R327: =INDEX(Detail!$C$1:$C$1001,MATCH(B327,Detail!$G$1:$G$1001,0),1) -> 158 | S327: =INDEX(Detail!$D$1:$D$1001,MATCH(B327,Detail!$G$1:$G$1001,0),1) -> 52 | T327: =INDEX(Detail!$E$1:$E$1001,MATCH(Main!B327,Detail!$G$1:$G$1001,0)) -> Gang Waringin No. 6 | U327: =INDEX(Detail!$B$1:$B$1001,MATCH(B327,Detail!$G$1:$G$1001,0),1) -> AB+ | V327: {=INDEX(Dosen!$B$3:$E$8,MATCH(Main!C327,Dosen!$A$3:$A$8,0),IF(AND(Main!A327>=1,Main!A327<=250),1,IF(AND(Main!A327>=251,Main!A327<=500),2,IF(AND(Main!A327>=501,Main!A327<=750),3,4))))} -> Pak Budi | W327: =_xlfn.XLOOKUP(B327,Detail!$G$1:$G$1001,Detail!$B$1:$B$1001) -> AB+
A328: 67 | B328: =CONCATENATE("C",TEXT(A328,"0000")) -> C0067 | C328: Kimia | D328: =VLOOKUP(B328,Detail!$G$1:$H$1001,2,FALSE) -> Siti Manullang | E328: 60 | F328: 65 | G328: 51 | H328: 58 | I328: 78 | J328: 72 | K328: 77 | L328: =IFERROR(VLOOKUP(B328,Absen!$A$1:$C$501,2,FALSE),"No") -> No | M328: =IF(L328="no",K328,K328-10)*10% -> 7.7 | N328: =SUM(E328*12.5%,F328*12.5%,H328*12.5%,I328*12.5%,G328*20%,J328*20%,M328) -> 64.925 | O328: =VLOOKUP(N328,Helper!$B$30:$C$35,2,TRUE) -> C | P328: =INDEX(Detail!$A$1:$A$1001,MATCH(B328,Detail!$G$1:$G$1001,0)) -> 37133 | Q328: =INDEX(Detail!$F$1:$F$1001,MATCH(Main!B328,Detail!$G$1:$G$1001,0)) -> Binjai | R328: =INDEX(Detail!$C$1:$C$1001,MATCH(B328,Detail!$G$1:$G$1001,0),1) -> 173 | S328: =INDEX(Detail!$D$1:$D$1001,MATCH(B328,Detail!$G$1:$G$1001,0),1) -> 93 | T328: =INDEX(Detail!$E$1:$E$1001,MATCH(Main!B328,Detail!$G$1:$G$1001,0)) -> Gg. Dipenogoro No. 2 | U328: =INDEX(Detail!$B$1:$B$1001,MATCH(B328,Detail!$G$1:$G$1001,0),1) -> A- | V328: {=INDEX(Dosen!$B$3:$E$8,MATCH(Main!C328,Dosen!$A$3:$A$8,0),IF(AND(Main!A328>=1,Main!A328<=250),1,IF(AND(Main!A328>=251,Main!A328<=500),2,IF(AND(Main!A328>=501,Main!A328<=750),3,4))))} -> Pak Budi | W328: =_xlfn.XLOOKUP(B328,Detail!$G$1:$G$1001,Detail!$B$1:$B$1001) -> A-
A329: 69 | B329: =CONCATENATE("C",TEXT(A329,"0000")) -> C0069 | C329: Kimia | D329: =VLOOKUP(B329,Detail!$G$1:$H$1001,2,FALSE) -> Niyaga Pradipta | E329: 78 | F329: 68 | G329: 38 | H329: 59 | I329: 56 | J329: 78 | K329: 91 | L329: =IFERROR(VLOOKUP(B329,Absen!$A$1:$C$501,2,FALSE),"No") -> No | M329: =IF(L329="no",K329,K329-10)*10% -> 9.1 | N329: =SUM(E329*12.5%,F329*12.5%,H329*12.5%,I329*12.5%,G329*20%,J329*20%,M329) -> 64.925 | O329: =VLOOKUP(N329,Helper!$B$30:$C$35,2,TRUE) -> C | P329: =INDEX(Detail!$A$1:$A$1001,MATCH(B329,Detail!$G$1:$G$1001,0)) -> 38030 | Q329: =INDEX(Detail!$F$1:$F$1001,MATCH(Main!B329,Detail!$G$1:$G$1001,0)) -> Surakarta | R329: =INDEX(Detail!$C$1:$C$1001,MATCH(B329,Detail!$G$1:$G$1001,0),1) -> 163 | S329: =INDEX(Detail!$D$1:$D$1001,MATCH(B329,Detail!$G$1:$G$1001,0),1) -> 48 | T329: =INDEX(Detail!$E$1:$E$1001,MATCH(Main!B329,Detail!$G$1:$G$1001,0)) -> Gg. Rawamangun No. 30 | U329: =INDEX(Detail!$B$1:$B$1001,MATCH(B329,Detail!$G$1:$G$1001,0),1) -> B+ | V329: {=INDEX(Dosen!$B$3:$E$8,MATCH(Main!C329,Dosen!$A$3:$A$8,0),IF(AND(Main!A329>=1,Main!A329<=250),1,IF(AND(Main!A329>=251,Main!A329<=500),2,IF(AND(Main!A329>=501,Main!A329<=750),3,4))))} -> Pak Budi | W329: =_xlfn.XLOOKUP(B329,Detail!$G$1:$G$1001,Detail!$B$1:$B$1001) -> B+
A330: 85 | B330: =CONCATENATE("C",TEXT(A330,"0000")) -> C0085 | C330: Kimia | D330: =VLOOKUP(B330,Detail!$G$1:$H$1001,2,FALSE) -> Gamani Susanti | E330: 61 | F330: 49 | G330: 56 | H330: 56 | I330: 52 | J330: 97 | K330: 63 | L330: =IFERROR(VLOOKUP(B330,Absen!$A$1:$C$501,2,FALSE),"No") -> No | M330: =IF(L330="no",K330,K330-10)*10% -> 6.3 | N330: =SUM(E330*12.5%,F330*12.5%,H330*12.5%,I330*12.5%,G330*20%,J330*20%,M330) -> 64.15 | O330: =VLOOKUP(N330,Helper!$B$30:$C$35,2,TRUE) -> C | P330: =INDEX(Detail!$A$1:$A$1001,MATCH(B330,Detail!$G$1:$G$1001,0)) -> 38394 | Q330: =INDEX(Detail!$F$1:$F$1001,MATCH(Main!B330,Detail!$G$1:$G$1001,0)) -> Pekanbaru | R330: =INDEX(Detail!$C$1:$C$1001,MATCH(B330,Detail!$G$1:$G$1001,0),1) -> 167 | S330: =INDEX(Detail!$D$1:$D$1001,MATCH(B330,Detail!$G$1:$G$1001,0),1) -> 91 | T330: =INDEX(Detail!$E$1:$E$1001,MATCH(Main!B330,Detail!$G$1:$G$1001,0)) -> Jalan Surapati No. 19 | U330: =INDEX(Detail!$B$1:$B$1001,MATCH(B330,Detail!$G$1:$G$1001,0),1) -> O+ | V330: {=INDEX(Dosen!$B$3:$E$8,MATCH(Main!C330,Dosen!$A$3:$A$8,0),IF(AND(Main!A330>=1,Main!A330<=250),1,IF(AND(Main!A330>=251,Main!A330<=500),2,IF(AND(Main!A330>=501,Main!A330<=750),3,4))))} -> Pak Budi | W330: =_xlfn.XLOOKUP(B330,Detail!$G$1:$G$1001,Detail!$B$1:$B$1001) -> O+
A331: 86 | B331: =CONCATENATE("C",TEXT(A331,"0000")) -> C0086 | C331: Kimia | D331: =VLOOKUP(B331,Detail!$G$1:$H$1001,2,FALSE) -> Elvin Tarihoran | E331: 81 | F331: 52 | G331: 56 | H331: 63 | I331: 80 | J331: 94 | K331: 71 | L331: =IFERROR(VLOOKUP(B331,Absen!$A$1:$C$501,2,FALSE),"No") -> No | M331: =IF(L331="no",K331,K331-10)*10% -> 7.1 | N331: =SUM(E331*12.5%,F331*12.5%,H331*12.5%,I331*12.5%,G331*20%,J331*20%,M331) -> 71.6 | O331: =VLOOKUP(N331,Helper!$B$30:$C$35,2,TRUE) -> B | P331: =INDEX(Detail!$A$1:$A$1001,MATCH(B331,Detail!$G$1:$G$1001,0)) -> 37793 | Q331: =INDEX(Detail!$F$1:$F$1001,MATCH(Main!B331,Detail!$G$1:$G$1001,0)) -> Bogor | R331: =INDEX(Detail!$C$1:$C$1001,MATCH(B331,Detail!$G$1:$G$1001,0),1) -> 167 | S331: =INDEX(Detail!$D$1:$D$1001,MATCH(B331,Detail!$G$1:$G$1001,0),1) -> 76 | T331: =INDEX(Detail!$E$1:$E$1001,MATCH(Main!B331,Detail!$G$1:$G$1001,0)) -> Gg. Monginsidi No. 76 | U331: =INDEX(Detail!$B$1:$B$1001,MATCH(B331,Detail!$G$1:$G$1001,0),1) -> O- | V331: {=INDEX(Dosen!$B$3:$E$8,MATCH(Main!C331,Dosen!$A$3:$A$8,0),IF(AND(Main!A331>=1,Main!A331<=250),1,IF(AND(Main!A331>=251,Main!A331<=500),2,IF(AND(Main!A331>=501,Main!A331<=750),3,4))))} -> Pak Budi | W331: =_xlfn.XLOOKUP(B331,Detail!$G$1:$G$1001,Detail!$B$1:$B$1001) -> O-
A332: 101 | B332: =CONCATENATE("C",TEXT(A332,"0000")) -> C0101 | C332: Kimia | D332: =VLOOKUP(B332,Detail!$G$1:$H$1001,2,FALSE) -> Dodo Hassanah | E332: 57 | F332: 43 | G332: 61 | H332: 50 | I332: 79 | J332: 82 | K332: 60 | L332: =IFERROR(VLOOKUP(B332,Absen!$A$1:$C$501,2,FALSE),"No") -> No | M332: =IF(L332="no",K332,K332-10)*10% -> 6 | N332: =SUM(E332*12.5%,F332*12.5%,H332*12.5%,I332*12.5%,G332*20%,J332*20%,M332) -> 63.225 | O332: =VLOOKUP(N332,Helper!$B$30:$C$35,2,TRUE) -> C | P332: =INDEX(Detail!$A$1:$A$1001,MATCH(B332,Detail!$G$1:$G$1001,0)) -> 37705 | Q332: =INDEX(Detail!$F$1:$F$1001,MATCH(Main!B332,Detail!$G$1:$G$1001,0)) -> Ternate | R332: =INDEX(Detail!$C$1:$C$1001,MATCH(B332,Detail!$G$1:$G$1001,0),1) -> 157 | S332: =INDEX(Detail!$D$1:$D$1001,MATCH(B332,Detail!$G$1:$G$1001,0),1) -> 91 | T332: =INDEX(Detail!$E$1:$E$1001,MATCH(Main!B332,Detail!$G$1:$G$1001,0)) -> Jalan Medokan Ayu No. 3 | U332: =INDEX(Detail!$B$1:$B$1001,MATCH(B332,Detail!$G$1:$G$1001,0),1) -> O+ | V332: {=INDEX(Dosen!$B$3:$E$8,MATCH(Main!C332,Dosen!$A$3:$A$8,0),IF(AND(Main!A332>=1,Main!A332<=250),1,IF(AND(Main!A332>=251,Main!A332<=500),2,IF(AND(Main!A332>=501,Main!A332<=750),3,4))))} -> Pak Budi | W332: =_xlfn.XLOOKUP(B332,Detail!$G$1:$G$1001,Detail!$B$1:$B$1001) -> O+
...

Sheet Detail
A1: Tanggal Lahir | B1: Golongan Darah | C1: Tinggi Badan | D1: Berat Badan | E1: Alamat | F1: Kota | G1: Code | H1: Nama
A2: 37749 | B2: A- | C2: 180 | D2: 55 | E2: Jalan Pasteur No. 97 | F2: Padang | G2: E0998 | H2: Ade Astuti
A3: 37973 | B3: A- | C3: 162 | D3: 82 | E3: Jl. Rungkut Industri No. 10 | F3: Denpasar | G3: E0806 | H3: Adiarja Sihotang
A4: 37684 | B4: A- | C4: 150 | D4: 47 | E4: Gang Rajawali Timur No. 36 | F4: Padang | G4: F0901 | H4: Adika Prastuti
A5: 38005 | B5: A- | C5: 158 | D5: 82 | E5: Jl. Rungkut Industri No. 5 | F5: Pontianak | G5: F0015 | H5: Adinata Permata
A6: 37596 | B6: A- | C6: 176 | D6: 90 | E6: Jl. Sadang Serang No. 14 | F6: Salatiga | G6: F0867 | H6: Aditya Pangestu
A7: 37902 | B7: A- | C7: 165 | D7: 69 | E7: Jalan M.H Thamrin No. 47 | F7: Tangerang | G7: A0301 | H7: Akarsana Lestari
A8: 37557 | B8: A- | C8: 152 | D8: 93 | E8: Jalan Sentot Alibasa No. 39 | F8: Cilegon | G8: B0467 | H8: Anita Suryatmi
A9: 38197 | B9: A- | C9: 176 | D9: 47 | E9: Gang K.H. Wahid Hasyim No. 25 | F9: Depok | G9: A0394 | H9: Anita Tamba
A10: 37016 | B10: A- | C10: 176 | D10: 61 | E10: Jl. Astana Anyar No. 2 | F10: Pagaralam | G10: E0366 | H10: Argono Wastuti
A11: 38014 | B11: A- | C11: 154 | D11: 71 | E11: Gang HOS. Cokroaminoto No. 41 | F11: Prabumulih | G11: B0960 | H11: Aris Purnawati
A12: 38283 | B12: A- | C12: 180 | D12: 76 | E12: Jl. Kutisari Selatan No. 43 | F12: Batam | G12: B0066 | H12: Arsipatra Lailasari
A13: 37102 | B13: A- | C13: 176 | D13: 60 | E13: Jl. Wonoayu No. 03 | F13: Surabaya | G13: A0500 | H13: Arsipatra Prasetya
... A1001: 37641 | B1001: O+ | C1001: 179 | D1001: 76 | E1001: Jalan S. Parman No. 85 | F1001: Cilegon | G1001: E0013 | H1001: Zulaikha Hasanah

Sheet Helper
A1: List Jurusan | B1: Rata-rata UTS | K1: Jurusan | L1: Jumlah ujian 2 | R1: jurusan | S1: Rata rata ujian 3 | T1: Rata-rata ujian 4
A2: Aktuaria | B2: =AVERAGEIFS(Main!$G$1:$G$1001,Main!$C$1:$C$1001,Helper!A14) -> 65.128834 | K2: Biologi | L2: =SUMIFS(Main!$F$1:$F$1001,Main!$C$1:$C$1001,Helper!A14) -> 9493 | R2: Biologi | S2: =AVERAGEIFS(Main!$H$1:$H$1001,Main!$C$1:$C$1001,Helper!R2) -> 62.494624 | T2: =AVERAGEIFS(Main!$I$1:$I$1001,Main!$C$1:$C$1001,Helper!R2) -> 71.005376
A3: Matematika | B3: =AVERAGEIFS(Main!$G$1:$G$1001,Main!$C$1:$C$1001,Helper!A15) -> 63.874214 | K3: Aktuaria | L3: =SUMIFS(Main!$F$1:$F$1001,Main!$C$1:$C$1001,Helper!A15) -> 9075 | R3: Aktuaria | S3: =AVERAGEIFS(Main!$H$1:$H$1001,Main!$C$1:$C$1001,Helper!R3) -> 62.128834 | T3: =AVERAGEIFS(Main!$I$1:$I$1001,Main!$C$1:$C$1001,Helper!R3) -> 73.521472 | U3: =T3-S3 -> 11.392638
A4: Kimia | B4: =AVERAGEIFS(Main!$G$1:$G$1001,Main!$C$1:$C$1001,Helper!A16) -> 63.645349 | K4: Fisika | L4: =SUMIFS(Main!$F$1:$F$1001,Main!$C$1:$C$1001,Helper!A16) -> 10010 | R4: Fisika | S4: =AVERAGEIFS(Main!$H$1:$H$1001,Main!$C$1:$C$1001,Helper!R4) -> 63.10625 | T4: =AVERAGEIFS(Main!$I$1:$I$1001,Main!$C$1:$C$1001,Helper!R4) -> 71.20625
A5: Fisika | B5: =AVERAGEIFS(Main!$G$1:$G$1001,Main!$C$1:$C$1001,Helper!A17) -> 62.825 | K5: Statistika | L5: =SUMIFS(Main!$F$1:$F$1001,Main!$C$1:$C$1001,Helper!A17) -> 9022 | R5: Statistika | S5: =AVERAGEIFS(Main!$H$1:$H$1001,Main!$C$1:$C$1001,Helper!R5) -> 62.3625 | T5: =AVERAGEIFS(Main!$I$1:$I$1001,Main!$C$1:$C$1001,Helper!R5) -> 72.025
A6: Biologi | B6: =AVERAGEIFS(Main!$G$1:$G$1001,Main!$C$1:$C$1001,Helper!A18) -> 62.322581 | K6: Matematika | L6: =SUMIFS(Main!$F$1:$F$1001,Main!$C$1:$C$1001,Helper!A18) -> 10745 | R6: Matematika | S6: =AVERAGEIFS(Main!$H$1:$H$1001,Main!$C$1:$C$1001,Helper!R6) -> 62.654088 | T6: =AVERAGEIFS(Main!$I$1:$I$1001,Main!$C$1:$C$1001,Helper!R6) -> 73.440252
A7: Statistika | B7: =AVERAGEIFS(Main!$G$1:$G$1001,Main!$C$1:$C$1001,Helper!A19) -> 62.19375 | K7: Kimia | L7: =SUMIFS(Main!F1:F1001,Main!C1:C1001,Helper!A19) -> 8949 | R7: Kimia | S7: =AVERAGEIFS(Main!$H$1:$H$1001,Main!$C$1:$C$1001,Helper!R7) -> 62.087209 | T7: =AVERAGEIFS(Main!$I$1:$I$1001,Main!$C$1:$C$1001,Helper!R7) -> 73.354651
R8: =_xlfn.FORMULATEXT(S2) -> =AVERAGEIFS(Main!$H$1:$H$1001;Main!$C$1:$C$1001;Helper!R2)
A13: List Jurusan | B13: Jumlah | C13: tidak pernah Absen | D13: abesen | E13: absen oktober | F13: absen september
A14: Aktuaria | B14: =COUNTIFS(Main!$C$1:$C$1001,Helper!A14) -> 163 | C14: =COUNTIFS(Main!$C$1:$C$1001,Helper!A14,Main!$L$1:$L$1001,"no") -> 80 | D14: =B14-C14 -> 83 | E14: =COUNTIF(Absen!C1:C501,10) -> 104 | F14: =COUNTIF(Absen!C1:C501,9) -> 94
A15: Matematika | B15: =COUNTIFS(Main!$C$1:$C$1001,Helper!A15) -> 159 | C15: =COUNTIFS(Main!$C$1:$C$1001,Helper!A15,Main!$L$1:$L$1001,"no") -> 76 | D15: =B15-C15 -> 83
A16: Kimia | B16: =COUNTIFS(Main!$C$1:$C$1001,Helper!A16) -> 172 | C16: =COUNTIFS(Main!$C$1:$C$1001,Helper!A16,Main!$L$1:$L$1001,"no") -> 77 | D16: =B16-C16 -> 95
A17: Fisika | B17: =COUNTIFS(Main!$C$1:$C$1001,Helper!A17) -> 160 | C17: =COUNTIFS(Main!$C$1:$C$1001,Helper!A17,Main!$L$1:$L$1001,"no") -> 85 | D17: =B17-C17 -> 75
A18: Biologi | B18: =COUNTIFS(Main!$C$1:$C$1001,Helper!A18) -> 186 | C18: =COUNTIFS(Main!$C$1:$C$1001,Helper!A18,Main!$L$1:$L$1001,"no") -> 98 | D18: =B18-C18 -> 88
A19: Statistika | B19: =COUNTIFS(Main!$C$1:$C$1001,Helper!A19) -> 160 | C19: =COUNTIFS(Main!$C$1:$C$1001,Helper!A19,Main!$L$1:$L$1001,"no") -> 84 | D19: =B19-C19 -> 76
B20: =SUM(B14:B19) -> 1000 | C20: =SUM(C14:C19) -> 500
A22: Jurusan | B22: Nilai akhir rata-rata | C22: Jumlah Ujian 1 | D22: Rata rata ujian 1 | E22: rata rata ujian 2 | F22: rata rata ujian 3 | G22: selisih ujian 1 dan 2 | H22: selisih ujian 2 dan 3
A23: Matematika | B23: =AVERAGEIF(Main!$C$1:$C$1001,Helper!A23,Main!$N$1:$N$1001) -> 67.472484 | C23: =SUMIFS(Main!$E$1:$E$1001,Main!$C$1:$C$1001,A23) -> 11547 | D23: =AVERAGEIFS(Main!$E$1:$E$1001,Main!$C$1:$C$1001,Helper!A23) -> 72.622642 | E23: =AVERAGEIFS(Main!$F$1:$F$1001,Main!$C$1:$C$1001,Helper!A23) -> 57.075472 | F23: =AVERAGEIFS(Main!$H$1:$H$1001,Main!$C$1:$C$1001,Helper!A23) -> 62.654088 | G23: =D23-E23 -> 15.54717 | H23: =F23-E23 -> 5.5786164
A24: Fisika | B24: =AVERAGEIF(Main!$C$1:$C$1001,Helper!A24,Main!$N$1:$N$1001) -> 67.210938 | C24: =SUMIFS(Main!$E$1:$E$1001,Main!$C$1:$C$1001,A24) -> 11462 | D24: =AVERAGEIFS(Main!$E$1:$E$1001,Main!$C$1:$C$1001,Helper!A24) -> 71.6375 | E24: =AVERAGEIFS(Main!$F$1:$F$1001,Main!$C$1:$C$1001,Helper!A24) -> 56.3875 | F24: =AVERAGEIFS(Main!$H$1:$H$1001,Main!$C$1:$C$1001,Helper!A24) -> 63.10625 | G24: =D24-E24 -> 15.25 | H24: =F24-E24 -> 6.71875
A25: Kimia | B25: =AVERAGEIF(Main!$C$1:$C$1001,Helper!A25,Main!$N$1:$N$1001) -> 67.426163 | C25: =SUMIFS(Main!$E$1:$E$1001,Main!$C$1:$C$1001,A25) -> 12426 | D25: =AVERAGEIFS(Main!$E$1:$E$1001,Main!$C$1:$C$1001,Helper!A25) -> 72.244186 | E25: =AVERAGEIFS(Main!$F$1:$F$1001,Main!$C$1:$C$1001,Helper!A25) -> 58.197674 | F25: =AVERAGEIFS(Main!$H$1:$H$1001,Main!$C$1:$C$1001,Helper!A25) -> 62.087209 | G25: =D25-E25 -> 14.046512 | H25: =F25-E25 -> 3.8895349
A26: Biologi | B26: =AVERAGEIF(Main!$C$1:$C$1001,Helper!A26,Main!$N$1:$N$1001) -> 66.926344 | C26: =SUMIFS(Main!$E$1:$E$1001,Main!$C$1:$C$1001,A26) -> 13592 | D26: =AVERAGEIFS(Main!$E$1:$E$1001,Main!$C$1:$C$1001,Helper!A26) -> 73.075269 | E26: =AVERAGEIFS(Main!$F$1:$F$1001,Main!$C$1:$C$1001,Helper!A26) -> 57.768817 | F26: =AVERAGEIFS(Main!$H$1:$H$1001,Main!$C$1:$C$1001,Helper!A26) -> 62.494624 | G26: =D26-E26 -> 15.306452 | H26: =F26-E26 -> 4.7258065
A27: Statistika | B27: =AVERAGEIF(Main!$C$1:$C$1001,Helper!A27,Main!$N$1:$N$1001) -> 66.756562 | C27: =SUMIFS(Main!$E$1:$E$1001,Main!$C$1:$C$1001,A27) -> 11771 | D27: =AVERAGEIFS(Main!$E$1:$E$1001,Main!$C$1:$C$1001,Helper!A27) -> 73.56875 | E27: =AVERAGEIFS(Main!$F$1:$F$1001,Main!$C$1:$C$1001,Helper!A27) -> 55.93125 | F27: =AVERAGEIFS(Main!$H$1:$H$1001,Main!$C$1:$C$1001,Helper!A27) -> 62.3625 | G27: =D27-E27 -> 17.6375 | H27: =F27-E27 -> 6.43125
A28: Aktuaria | B28: =AVERAGEIF(Main!$C$1:$C$1001,Helper!A28,Main!$N$1:$N$1001) -> 67.56411 | C28: =SUMIFS(Main!$E$1:$E$1001,Main!$C$1:$C$1001,A28) -> 12042 | D28: =AVERAGEIFS(Main!$E$1:$E$1001,Main!$C$1:$C$1001,Helper!A28) -> 73.877301 | E28: =AVERAGEIFS(Main!$F$1:$F$1001,Main!$C$1:$C$1001,Helper!A28) -> 58.239264 | F28: =AVERAGEIFS(Main!$H$1:$H$1001,Main!$C$1:$C$1001,Helper!A28) -> 62.128834 | G28: =D28-E28 -> 15.638037 | H28: =F28-E28 -> 3.8895706
B30: 0 | C30: E | D30: GRADE A | E30: Grade C | F30: Grade
B31: 40.01 | C31: D | D31: =COUNTIF(Main!O1:O1001,"A") -> 17 | E31: =COUNTIF(Main!O1:O1001,"c") -> 556 | F31: =COUNTIF(Main!O1:O1001,"D") -> 123
B32: 60.01 | C32: C | E32: =E31*100%/1000 -> 0.556
B33: 70.01 | C33: B
B34: 80.01 | C34: A
B35: 90.01 | C35: A+
A37: Rata rata tinggi badan asal surabaya
A38: =AVERAGEIFS(Main!R1:R1001,Main!Q1:Q1001,"Surabaya") -> 161

Sheet Soal
B1: Pertanyaan | C1: Jawaban | D1: Check
A2: 1 | B2: Berapa data dari kolom Jurusan yang Invalid (Tidak Valid)? | C2: 58 | D2: =IF(C2=58,2,IF(C2="",1,0)) -> 2
