Workbook

Sheet Original
A1: Nama Karyawan | B1: Tanggal Lahir | C1: Tahun lahir | D1: Usia | E1: Divisi | F1: Mulai Kerja | G1: Tahun Mulai Kerja | H1: Gaji Pokok | I1: Bonus | J1: nama > 2 kata
A2: Kara Lynn Joyce | B2: 35342 | C2: =YEAR(Table1[[#This Row],[Tanggal Lahir]]) -> 1996 | D2: =YEARFRAC(B2,$L$2) -> 25.977778 | E2: Marketing and Sales | F2: 39758 | G2: =YEAR(F2) -> 2008 | H2: =IF(G2<= 2008,18000000,IF(AND(G2>=2009,G2<=2013),13000000,IF(AND(G2>=2014,G2<=2019),9000000,6800000))) -> 18000000 | I2: 5 | J2: =SUM(LEN(A2)-LEN(SUBSTITUTE(A2," ",""))+1) -> 3 | K2: Batas Tanggal Usia | L2: 44830
A3: Michael Phelps | B3: 34917 | C3: =YEAR(Table1[[#This Row],[Tanggal Lahir]]) -> 1995 | D3: =YEARFRAC(B3,$L$2) -> 27.138889 | E3: Marketing and Sales | F3: 40759 | G3: =YEAR(F3) -> 2011 | H3: =IF(G3<= 2008,18000000,IF(AND(G3>=2009,G3<=2013),13000000,IF(AND(G3>=2014,G3<=2019),9000000,6800000))) -> 13000000 | I3: 2 | J3: =SUM(LEN(A3)-LEN(SUBSTITUTE(A3," ",""))+1) -> 2
A4: Natalie Coughlin | B4: 35877 | C4: =YEAR(Table1[[#This Row],[Tanggal Lahir]]) -> 1998 | D4: =YEARFRAC(B4,$L$2) -> 24.508333 | E4: After Sales | F4: 41969 | G4: =YEAR(F4) -> 2014 | H4: =IF(G4<= 2008,18000000,IF(AND(G4>=2009,G4<=2013),13000000,IF(AND(G4>=2014,G4<=2019),9000000,6800000))) -> 9000000 | I4: 5 | J4: =SUM(LEN(A4)-LEN(SUBSTITUTE(A4," ",""))+1) -> 2
A5: Aleksey Nemov | B5: 37064 | C5: =YEAR(Table1[[#This Row],[Tanggal Lahir]]) -> 2001 | D5: =YEARFRAC(B5,$L$2) -> 21.261111 | E5: Marketing and Sales | F5: 42523 | G5: =YEAR(F5) -> 2016 | H5: =IF(G5<= 2008,18000000,IF(AND(G5>=2009,G5<=2013),13000000,IF(AND(G5>=2014,G5<=2019),9000000,6800000))) -> 9000000 | I5: 4 | J5: =SUM(LEN(A5)-LEN(SUBSTITUTE(A5," ",""))+1) -> 2
A6: Alicia Coutts | B6: 37510 | C6: =YEAR(Table1[[#This Row],[Tanggal Lahir]]) -> 2002 | D6: =YEARFRAC(B6,$L$2) -> 20.041667 | E6: After Sales | F6: 40431 | G6: =YEAR(F6) -> 2010 | H6: =IF(G6<= 2008,18000000,IF(AND(G6>=2009,G6<=2013),13000000,IF(AND(G6>=2014,G6<=2019),9000000,6800000))) -> 13000000 | I6: 6 | J6: =SUM(LEN(A6)-LEN(SUBSTITUTE(A6," ",""))+1) -> 2
A7: Missy Franklin | B7: 36188 | C7: =YEAR(Table1[[#This Row],[Tanggal Lahir]]) -> 1999 | D7: =YEARFRAC(B7,$L$2) -> 23.661111 | E7: Administrasi | F7: 38777 | G7: =YEAR(F7) -> 2006 | H7: =IF(G7<= 2008,18000000,IF(AND(G7>=2009,G7<=2013),13000000,IF(AND(G7>=2014,G7<=2019),9000000,6800000))) -> 18000000 | I7: 4 | J7: =SUM(LEN(A7)-LEN(SUBSTITUTE(A7," ",""))+1) -> 2
A8: Ryan Lochte | B8: 37963 | C8: =YEAR(Table1[[#This Row],[Tanggal Lahir]]) -> 2003 | D8: =YEARFRAC(B8,$L$2) -> 18.8 | E8: After Sales | F8: 41903 | G8: =YEAR(F8) -> 2014 | H8: =IF(G8<= 2008,18000000,IF(AND(G8>=2009,G8<=2013),13000000,IF(AND(G8>=2014,G8<=2019),9000000,6800000))) -> 9000000 | I8: 5 | J8: =SUM(LEN(A8)-LEN(SUBSTITUTE(A8," ",""))+1) -> 2
A9: Irina Tolkunova | B9: 37305 | C9: =YEAR(Table1[[#This Row],[Tanggal Lahir]]) -> 2002 | D9: =YEARFRAC(B9,$L$2) -> 20.605556 | E9: After Sales | F9: 38519 | G9: =YEAR(F9) -> 2005 | H9: =IF(G9<= 2008,18000000,IF(AND(G9>=2009,G9<=2013),13000000,IF(AND(G9>=2014,G9<=2019),9000000,6800000))) -> 18000000 | I9: 6 | J9: =SUM(LEN(A9)-LEN(SUBSTITUTE(A9," ",""))+1) -> 2
A10: Allison Schmitt | B10: 36010 | C10: =YEAR(Table1[[#This Row],[Tanggal Lahir]]) -> 1998 | D10: =YEARFRAC(B10,$L$2) -> 24.147222 | E10: After Sales | F10: 39223 | G10: =YEAR(F10) -> 2007 | H10: =IF(G10<= 2008,18000000,IF(AND(G10>=2009,G10<=2013),13000000,IF(AND(G10>=2014,G10<=2019),9000000,6800000))) -> 18000000 | I10: 2 | J10: =SUM(LEN(A10)-LEN(SUBSTITUTE(A10," ",""))+1) -> 2
A11: Ian Thorpe | B11: 36391 | C11: =YEAR(Table1[[#This Row],[Tanggal Lahir]]) -> 1999 | D11: =YEARFRAC(B11,$L$2) -> 23.102778 | E11: Marketing and Sales | F11: 42117 | G11: =YEAR(F11) -> 2015 | H11: =IF(G11<= 2008,18000000,IF(AND(G11>=2009,G11<=2013),13000000,IF(AND(G11>=2014,G11<=2019),9000000,6800000))) -> 9000000 | I11: 2 | J11: =SUM(LEN(A11)-LEN(SUBSTITUTE(A11," ",""))+1) -> 2
A12: Dara Torres | B12: 37330 | C12: =YEAR(Table1[[#This Row],[Tanggal Lahir]]) -> 2002 | D12: =YEARFRAC(B12,$L$2) -> 20.530556 | E12: Administrasi | F12: 44355 | G12: =YEAR(F12) -> 2021 | H12: =IF(G12<= 2008,18000000,IF(AND(G12>=2009,G12<=2013),13000000,IF(AND(G12>=2014,G12<=2019),9000000,6800000))) -> 6800000 | I12: 1 | J12: =SUM(LEN(A12)-LEN(SUBSTITUTE(A12," ",""))+1) -> 2
A13: Cindy Klassen | B13: 36728 | C13: =YEAR(Table1[[#This Row],[Tanggal Lahir]]) -> 2000 | D13: =YEARFRAC(B13,$L$2) -> 22.180556 | E13: After Sales | F13: 39022 | G13: =YEAR(F13) -> 2006 | H13: =IF(G13<= 2008,18000000,IF(AND(G13>=2009,G13<=2013),13000000,IF(AND(G13>=2014,G13<=2019),9000000,6800000))) -> 18000000 | I13: 4 | J13: =SUM(LEN(A13)-LEN(SUBSTITUTE(A13," ",""))+1) -> 2
A14: Nastia Liukin | B14: 35693 | C14: =YEAR(Table1[[#This Row],[Tanggal Lahir]]) -> 1997 | D14: =YEARFRAC(B14,$L$2) -> 25.016667 | E14: After SaIes | F14: 40071 | G14: =YEAR(F14) -> 2009 | H14: =IF(G14<= 2008,18000000,IF(AND(G14>=2009,G14<=2013),13000000,IF(AND(G14>=2014,G14<=2019),9000000,6800000))) -> 13000000 | I14: 3 | J14: =SUM(LEN(A14)-LEN(SUBSTITUTE(A14," ",""))+1) -> 2
... A16: Sun Yang | B16: 35277 | C16: =YEAR(Table1[[#This Row],[Tanggal Lahir]]) -> 1996 | D16: =YEARFRAC(B16,$L$2) -> 26.155556 | E16: After Sales | F16: 39242 | G16: =YEAR(F16) -> 2007 | H16: =IF(G16<= 2008,18000000,IF(AND(G16>=2009,G16<=2013),13000000,IF(AND(G16>=2014,G16<=2019),9000000,6800000))) -> 18000000 | I16: 5 | J16: =SUM(LEN(A16)-LEN(SUBSTITUTE(A16," ",""))+1) -> 2
A17: Kirsty Coventry | B17: 34970 | C17: =YEAR(Table1[[#This Row],[Tanggal Lahir]]) -> 1995 | D17: =YEARFRAC(B17,$L$2) -> 26.994444 | E17: After Sales | F17: 40523 | G17: =YEAR(F17) -> 2010 | H17: =IF(G17<= 2008,18000000,IF(AND(G17>=2009,G17<=2013),13000000,IF(AND(G17>=2014,G17<=2019),9000000,6800000))) -> 13000000 | I17: 1 | J17: =SUM(LEN(A17)-LEN(SUBSTITUTE(A17," ",""))+1) -> 2 | K17: 1 | L17: Tahun Masuk Kerja | M17: Gaji Pokok/Bulan
A18: Inge de Bruijn | B18: 35911 | C18: =YEAR(Table1[[#This Row],[Tanggal Lahir]]) -> 1998 | D18: =YEARFRAC(B18,$L$2) -> 24.416667 | E18: After Sales | F18: 42492 | G18: =YEAR(F18) -> 2016 | H18: =IF(G18<= 2008,18000000,IF(AND(G18>=2009,G18<=2013),13000000,IF(AND(G18>=2014,G18<=2019),9000000,6800000))) -> 9000000 | I18: 1 | J18: =SUM(LEN(A18)-LEN(SUBSTITUTE(A18," ",""))+1) -> 3 | L18: 2008 dan sebelumnya | M18: 18000000
A19: Petria Thomas | B19: 34671 | C19: =YEAR(Table1[[#This Row],[Tanggal Lahir]]) -> 1994 | D19: =YEARFRAC(B19,$L$2) -> 27.813889 | E19: Administrasi | F19: 40872 | G19: =YEAR(F19) -> 2011 | H19: =IF(G19<= 2008,18000000,IF(AND(G19>=2009,G19<=2013),13000000,IF(AND(G19>=2014,G19<=2019),9000000,6800000))) -> 13000000 | I19: 3 | J19: =SUM(LEN(A19)-LEN(SUBSTITUTE(A19," ",""))+1) -> 2 | L19: 2009 - 2013 | M19: 13000000
A20: Gary Hall Jr. | B20: 37958 | C20: =YEAR(Table1[[#This Row],[Tanggal Lahir]]) -> 2003 | D20: =YEARFRAC(B20,$L$2) -> 18.813889 | E20: After Sales | F20: 39679 | G20: =YEAR(F20) -> 2008 | H20: =IF(G20<= 2008,18000000,IF(AND(G20>=2009,G20<=2013),13000000,IF(AND(G20>=2014,G20<=2019),9000000,6800000))) -> 18000000 | I20: 3 | J20: =SUM(LEN(A20)-LEN(SUBSTITUTE(A20," ",""))+1) -> 3 | L20: 2014 - 2019 | M20: 9000000
A21: Michael Klim | B21: 35593 | C21: =YEAR(Table1[[#This Row],[Tanggal Lahir]]) -> 1997 | D21: =YEARFRAC(B21,$L$2) -> 25.288889 | E21: After Sales | F21: 44199 | G21: =YEAR(F21) -> 2021 | H21: =IF(G21<= 2008,18000000,IF(AND(G21>=2009,G21<=2013),13000000,IF(AND(G21>=2014,G21<=2019),9000000,6800000))) -> 6800000 | I21: 3 | J21: =SUM(LEN(A21)-LEN(SUBSTITUTE(A21," ",""))+1) -> 2 | L21: Setelah 2019 | M21: 6800000
A22: Susie O'Neill | B22: 36189 | C22: =YEAR(Table1[[#This Row],[Tanggal Lahir]]) -> 1999 | D22: =YEARFRAC(B22,$L$2) -> 23.658333 | E22: After Sales | F22: 42006 | G22: =YEAR(F22) -> 2015 | H22: =IF(G22<= 2008,18000000,IF(AND(G22>=2009,G22<=2013),13000000,IF(AND(G22>=2014,G22<=2019),9000000,6800000))) -> 9000000 | I22: 1 | J22: =SUM(LEN(A22)-LEN(SUBSTITUTE(A22," ",""))+1) -> 2
A23: Jenny Thompson | B23: 35911 | C23: =YEAR(Table1[[#This Row],[Tanggal Lahir]]) -> 1998 | D23: =YEARFRAC(B23,$L$2) -> 24.416667 | E23: Marketing and Sales | F23: 41728 | G23: =YEAR(F23) -> 2014 | H23: =IF(G23<= 2008,18000000,IF(AND(G23>=2009,G23<=2013),13000000,IF(AND(G23>=2014,G23<=2019),9000000,6800000))) -> 9000000 | I23: 4 | J23: =SUM(LEN(A23)-LEN(SUBSTITUTE(A23," ",""))+1) -> 2
A24: Pieter van Hoogenband | B24: 36138 | C24: =YEAR(Table1[[#This Row],[Tanggal Lahir]]) -> 1998 | D24: =YEARFRAC(B24,$L$2) -> 23.797222 | E24: Marketing and Sales | F24: 40105 | G24: =YEAR(F24) -> 2009 | H24: =IF(G24<= 2008,18000000,IF(AND(G24>=2009,G24<=2013),13000000,IF(AND(G24>=2014,G24<=2019),9000000,6800000))) -> 13000000 | I24: 6 | J24: =SUM(LEN(A24)-LEN(SUBSTITUTE(A24," ",""))+1) -> 3
A25: An Hyeon Su | B25: 35364 | C25: =YEAR(Table1[[#This Row],[Tanggal Lahir]]) -> 1996 | D25: =YEARFRAC(B25,$L$2) -> 25.916667 | E25: After Sales | F25: 42943 | G25: =YEAR(F25) -> 2017 | H25: =IF(G25<= 2008,18000000,IF(AND(G25>=2009,G25<=2013),13000000,IF(AND(G25>=2014,G25<=2019),9000000,6800000))) -> 9000000 | I25: 3 | J25: =SUM(LEN(A25)-LEN(SUBSTITUTE(A25," ",""))+1) -> 3
A26: Aliya Mustafina | B26: 35986 | C26: =YEAR(Table1[[#This Row],[Tanggal Lahir]]) -> 1998 | D26: =YEARFRAC(B26,$L$2) -> 24.211111 | E26: Administrasi | F26: 43003 | G26: =YEAR(F26) -> 2017 | H26: =IF(G26<= 2008,18000000,IF(AND(G26>=2009,G26<=2013),13000000,IF(AND(G26>=2014,G26<=2019),9000000,6800000))) -> 9000000 | I26: 6 | J26: =SUM(LEN(A26)-LEN(SUBSTITUTE(A26," ",""))+1) -> 2
A27: Shawn Johnson | B27: 37704 | C27: =YEAR(Table1[[#This Row],[Tanggal Lahir]]) -> 2003 | D27: =YEARFRAC(B27,$L$2) -> 19.505556 | E27: Marketing and Sales | F27: 44624 | G27: =YEAR(F27) -> 2022 | H27: =IF(G27<= 2008,18000000,IF(AND(G27>=2009,G27<=2013),13000000,IF(AND(G27>=2014,G27<=2019),9000000,6800000))) -> 6800000 | I27: 6 | J27: =SUM(LEN(A27)-LEN(SUBSTITUTE(A27," ",""))+1) -> 2
A28: Dmitry Sautin | B28: 37418 | C28: =YEAR(Table1[[#This Row],[Tanggal Lahir]]) -> 2002 | D28: =YEARFRAC(B28,$L$2) -> 20.291667 | E28: After Sales | F28: 40072 | G28: =YEAR(F28) -> 2009 | H28: =IF(G28<= 2008,18000000,IF(AND(G28>=2009,G28<=2013),13000000,IF(AND(G28>=2014,G28<=2019),9000000,6800000))) -> 13000000 | I28: 6 | J28: =SUM(LEN(A28)-LEN(SUBSTITUTE(A28," ",""))+1) -> 2
A29: Libby Lenton Trickett | B29: 37488 | C29: =YEAR(Table1[[#This Row],[Tanggal Lahir]]) -> 2002 | D29: =YEARFRAC(B29,$L$2) -> 20.1 | E29: After Sales | F29: 44331 | G29: =YEAR(F29) -> 2021 | H29: =IF(G29<= 2008,18000000,IF(AND(G29>=2009,G29<=2013),13000000,IF(AND(G29>=2014,G29<=2019),9000000,6800000))) -> 6800000 | I29: 3 | J29: =SUM(LEN(A29)-LEN(SUBSTITUTE(A29," ",""))+1) -> 3
A30: Leontien Zijlaard Moorsel | B30: 37997 | C30: =YEAR(Table1[[#This Row],[Tanggal Lahir]]) -> 2004 | D30: =YEARFRAC(B30,$L$2) -> 18.708333 | E30: Marketing and Sales | F30: 38566 | G30: =YEAR(F30) -> 2005 | H30: =IF(G30<= 2008,18000000,IF(AND(G30>=2009,G30<=2013),13000000,IF(AND(G30>=2014,G30<=2019),9000000,6800000))) -> 18000000 | I30: 3 | J30: =SUM(LEN(A30)-LEN(SUBSTITUTE(A30," ",""))+1) -> 3
A31: Petter Northug Jr. | B31: 36215 | C31: =YEAR(Table1[[#This Row],[Tanggal Lahir]]) -> 1999 | D31: =YEARFRAC(B31,$L$2) -> 23.588889 | E31: After Sales | F31: 38760 | G31: =YEAR(F31) -> 2006 | H31: =IF(G31<= 2008,18000000,IF(AND(G31>=2009,G31<=2013),13000000,IF(AND(G31>=2014,G31<=2019),9000000,6800000))) -> 18000000 | I31: 5 | J31: =SUM(LEN(A31)-LEN(SUBSTITUTE(A31," ",""))+1) -> 3
A32: Ole Einar Bjørndalen | B32: 37761 | C32: =YEAR(Table1[[#This Row],[Tanggal Lahir]]) -> 2003 | D32: =YEARFRAC(B32,$L$2) -> 19.35 | E32: After Sales | F32: 41687 | G32: =YEAR(F32) -> 2014 | H32: =IF(G32<= 2008,18000000,IF(AND(G32>=2009,G32<=2013),13000000,IF(AND(G32>=2014,G32<=2019),9000000,6800000))) -> 9000000 | I32: 5 | J32: =SUM(LEN(A32)-LEN(SUBSTITUTE(A32," ",""))+1) -> 3
A33: Janica Kostelic | B33: 34845 | C33: =YEAR(Table1[[#This Row],[Tanggal Lahir]]) -> 1995 | D33: =YEARFRAC(B33,$L$2) -> 27.333333 | E33: After Sales | F33: 39032 | G33: =YEAR(F33) -> 2006 | H33: =IF(G33<= 2008,18000000,IF(AND(G33>=2009,G33<=2013),13000000,IF(AND(G33>=2014,G33<=2019),9000000,6800000))) -> 18000000 | I33: 5 | J33: =SUM(LEN(A33)-LEN(SUBSTITUTE(A33," ",""))+1) -> 2
... A155: Serena Williams | B155: 36555 | C155: =YEAR(Table1[[#This Row],[Tanggal Lahir]]) -> 2000 | D155: =YEARFRAC(B155,$L$2) -> 22.655556 | E155: After Sales | F155: 38251 | G155: =YEAR(F155) -> 2004 | H155: =IF(G155<= 2008,18000000,IF(AND(G155>=2009,G155<=2013),13000000,IF(AND(G155>=2014,G155<=2019),9000000,6800000))) -> 18000000 | I155: 5 | J155: =SUM(LEN(A155)-LEN(SUBSTITUTE(A155," ",""))+1) -> 2
A156: Fernando González | B156: 36120 | C156: =YEAR(Table1[[#This Row],[Tanggal Lahir]]) -> 1998 | D156: =YEARFRAC(B156,$L$2) -> 23.847222 | E156: After Sales | F156: 44459 | G156: =YEAR(F156) -> 2021 | H156: =IF(G156<= 2008,18000000,IF(AND(G156>=2009,G156<=2013),13000000,IF(AND(G156>=2014,G156<=2019),9000000,6800000))) -> 6800000 | I156: 3 | J156: =SUM(LEN(A156)-LEN(SUBSTITUTE(A156," ",""))+1) -> 2 | N156: {=_xlfn.UNIQUE(#REF!)} -> #REF!
A157: Nicolás Massú | B157: 37545 | C157: =YEAR(Table1[[#This Row],[Tanggal Lahir]]) -> 2002 | D157: =YEARFRAC(B157,$L$2) -> 19.944444 | E157: After Sales | F157: 41796 | G157: =YEAR(F157) -> 2014 | H157: =IF(G157<= 2008,18000000,IF(AND(G157>=2009,G157<=2013),13000000,IF(AND(G157>=2014,G157<=2019),9000000,6800000))) -> 9000000 | I157: 1 | J157: =SUM(LEN(A157)-LEN(SUBSTITUTE(A157," ",""))+1) -> 2
A158: Venus Williams | B158: 36543 | C158: =YEAR(Table1[[#This Row],[Tanggal Lahir]]) -> 2000 | D158: =YEARFRAC(B158,$L$2) -> 22.688889 | E158: After Sales | F158: 44491 | G158: =YEAR(F158) -> 2021 | H158: =IF(G158<= 2008,18000000,IF(AND(G158>=2009,G158<=2013),13000000,IF(AND(G158>=2014,G158<=2019),9000000,6800000))) -> 6800000 | I158: 1 | J158: =SUM(LEN(A158)-LEN(SUBSTITUTE(A158," ",""))+1) -> 2
A159: Ona Carbonell | B159: 37032 | C159: =YEAR(Table1[[#This Row],[Tanggal Lahir]]) -> 2001 | D159: =YEARFRAC(B159,$L$2) -> 21.347222 | E159: Marketing and Sales | F159: 41306 | G159: =YEAR(F159) -> 2013 | H159: =IF(G159<= 2008,18000000,IF(AND(G159>=2009,G159<=2013),13000000,IF(AND(G159>=2014,G159<=2019),9000000,6800000))) -> 13000000 | I159: 4 | J159: =SUM(LEN(A159)-LEN(SUBSTITUTE(A159," ",""))+1) -> 2
A160: Andrea Fuentes | B160: 35254 | C160: =YEAR(Table1[[#This Row],[Tanggal Lahir]]) -> 1996 | D160: =YEARFRAC(B160,$L$2) -> 26.216667 | E160: After Sales | F160: 42890 | G160: =YEAR(F160) -> 2017 | H160: =IF(G160<= 2008,18000000,IF(AND(G160>=2009,G160<=2013),13000000,IF(AND(G160>=2014,G160<=2019),9000000,6800000))) -> 9000000 | I160: 1 | J160: =SUM(LEN(A160)-LEN(SUBSTITUTE(A160," ",""))+1) -> 2
A161: Huang Xuechen | B161: 35279 | C161: =YEAR(Table1[[#This Row],[Tanggal Lahir]]) -> 1996 | D161: =YEARFRAC(B161,$L$2) -> 26.15 | E161: Administrasi | F161: 41761 | G161: =YEAR(F161) -> 2014 | H161: =IF(G161<= 2008,18000000,IF(AND(G161>=2009,G161<=2013),13000000,IF(AND(G161>=2014,G161<=2019),9000000,6800000))) -> 9000000 | I161: 1 | J161: =SUM(LEN(A161)-LEN(SUBSTITUTE(A161," ",""))+1) -> 2
A162: Nataliya Ishchenko | B162: 35440 | C162: =YEAR(Table1[[#This Row],[Tanggal Lahir]]) -> 1997 | D162: =YEARFRAC(B162,$L$2) -> 25.711111 | E162: After Sales | F162: 43043 | G162: =YEAR(F162) -> 2017 | H162: =IF(G162<= 2008,18000000,IF(AND(G162>=2009,G162<=2013),13000000,IF(AND(G162>=2014,G162<=2019),9000000,6800000))) -> 9000000 | I162: 1 | J162: =SUM(LEN(A162)-LEN(SUBSTITUTE(A162," ",""))+1) -> 2
...

Sheet Helper
A2: 1 | B2: Tahun Masuk Kerja | C2: Gaji Pokok/Bulan
B3: 2008 dan sebelumnya | C3: 18000000
B4: 2009 - 2013 | C4: 13000000
B5: 2014 - 2019 | C5: 9000000
B6: Setelah 2019 | C6: 6800000
A8: 2 | B8: Divisi :
B9: Marketing and Sales | C9: =COUNTIF(Table1[[#Headers],[#Data],[Divisi]],Helper!B9) -> 194 | D9: =_xlfn.FORMULATEXT(C9) -> =COUNTIF(Table1[[#Headers];[#Data];[Divisi]];Helper!B9)
B10: After Sales | C10: =COUNTIF(Table1[[#Headers],[#Data],[Divisi]],Helper!B10) -> 587 | D10: =_xlfn.FORMULATEXT(C10) -> =COUNTIF(Table1[[#Headers];[#Data];[Divisi]];Helper!B10)
B11: Administrasi | C11: =COUNTIF(Table1[[#Headers],[#Data],[Divisi]],Helper!B11) -> 189 | D11: =_xlfn.FORMULATEXT(C11) -> =COUNTIF(Table1[[#Headers];[#Data];[Divisi]];Helper!B11)
C12: =SUM(C9:C11) -> 970 | D12: =_xlfn.FORMULATEXT(C12) -> =SUM(C9:C11)
C13: =SUM(Table1[[#Data],[#Totals],[Divisi]]) -> 993 | D13: hasil perhitungan dari jumlah seluruh data di tabel original
C14: =C13-C12 -> 23 | D14: jawaban dari soal Ada berapakah nama Divisi yang salah ketik
A16: 3 | B16: total jumlah usia karyawan
B17: =SUM(Original!D2:D994) -> 23344.781
A18: 4 | B18: Berapa banyak karyawan yang lahir di atas tahun 2000?
B19: =COUNTIF(Table1[[#Headers],[#Data],[Tahun lahir]],">2000") -> 312 | C19: =_xlfn.FORMULATEXT(B19) -> =COUNTIF(Table1[[#Headers];[#Data];[Tahun lahir]];">2000")
A21: 5 | B21: Kelompok usia manakah yang mendapatkan nominal bonus paling tinggi?
B23: usia | C23: bonus
B24: 23 | C24: =SUM(Original!I1:I925) -> 3230
B25: 24 | C25: =SUM(Original!I1:I992) -> 3485
B26: 25 | C26: =SUM(Original!I1:I986) -> 3461
B27: 26 | C27: =SUM(Original!I1:I981) -> 3444
A29: 6 | B29: jumlah karyawan yang namanya memiliki lebih dari 2 kata?
B30: =COUNTIF(Table1[[#Headers],[#Data],[ nama > 2 kata]],">2") -> 141 | C30: =_xlfn.FORMULATEXT(B30) -> =COUNTIF(Table1[[#Headers];[#Data];[ nama > 2 kata]];">2")
A32: 7 | B32: total jumlah gaji untuk karyawan divisi "administrasi" yang masuk pada tahun 2019
B34: divisi | C34: tahun masuk | D34: total gaji
B35: administrasi | C35: 2019 | D35: =SUMIFS(Table1[[#Headers],[#Data],[Gaji Pokok]],Table1[[#Headers],[#Data],[Divisi]],Helper!B35,Table1[[#Headers],[#Data],[Tahun Mulai Kerja ]],Helper!C35) -> 108000000
